Workbook

Sheet item
A1: CONFIG_NAME | B1: item | C1: 配置名, 如果没有这个字段, 则这个Sheet不会导出
A2: CONFIG_DESCRIPTION | B2: 所有球杆、服装、球桌、道具等物品的统一id | C2: 可选, 配置文件描述.
A3: COLOR_COMMENT | B3: comment | C3: 注释背景颜色
A4: COLOR_COLUMN_INFO | B4: column_info
A5: RELATED_CONFIG | C5: 可选, 关联的表格
A6: TABLE_HEAD_LEN | B6: 4 | C6: 可选, 默认为3, 字段描述的长度.
A7: TABLE_PROPERTY
A8: TABLE_PROPERTY_RELATED
A11: 序号 | B11: 名称语言序号 | C11: 参考中文名 | D11: 描述语言序号 | E11: 参考中文描述 | F11: 物品类型 | G11: 使用类型 | H11: 预览图 | I11: 模型 | J11: 特效调整 | K11: 品质等级 | L11: 功能标签 | M11: 解释字段1 | N11: 背包提示类型 | O11: 解锁等级 | P11: 钻石定价 | Q11: 对局内球杆 | R11: 女生名称 | S11: 参考中文 | T11: 描述语言序号 | U11: 参考描述
A12: id | B12: name | C12: name_ch | D12: des | E12: des_ch | F12: type | G12: type_use | H12: icon | I12: mode | J12: effects_adjust | K12: quality | L12: tag | M12: field | N12: type_tips | O12: level | P12: value | Q12: cue_ingame | R12: name_girl | S12: name_ch | T12: des_girl | U12: name_ch
A13: int32 | B13: int32 | C13: string | D13: int32 | E13: string | F13: int32 | G13: string | H13: string | I13: string | J13: int32 | K13: int32 | L13: int32 | M13: string | N13: int32 | O13: int32 | P13: string | Q13: string | R13: int32 | S13: string | T13: int32 | U13: string
A14: key,lua,pb,json | B14: lua,pb,json | C14: vb | D14: lua,pb,json | E14: vb | F14: lua,pb,json | G14: lua,pb,json | H14: lua,pb,json | I14: lua,pb,json | J14: lua,pb,json | K14: lua,pb,json | L14: lua,pb,json | M14: lua,pb,json | N14: lua,pb,json | O14: lua,pb,json | P14: lua,pb,json | Q14: lua,pb,json | R14: lua,pb,json | S14: vb | T14: lua,pb,json | U14: vb
B15: 0 | C15: 0 | D15: 0 | E15: 0 | F15: 8 | G15: 0 | H15: icon_1 | I15: 0 | J15: 1 | K15: 0 | L15: 0 | M15: 0 | N15: 0 | O15: 0 | P15: 0 | Q15: 0 | R15: 0 | S15: 0 | T15: 0 | U15: 0
A16: 1 | B16: 1000001 | C16: 钻石 | D16: 1000002 | E16: 可用于兑换金币、购买道具等。 | F16: 0 | G16: 0 | H16: ="icon_"&A16 -> icon_1 | K16: 5 | L16: 0 | M16: 0 | N16: 0 | O16: 0 | P16: 1
A17: 2 | B17: 1000003 | C17: 金币 | D17: 1000004 | E17: 通用货币：可用于对局消耗、商城购买等。 | F17: 0 | G17: 0 | H17: ="icon_"&A17 -> icon_2 | K17: 4 | L17: 0 | M17: 0 | N17: 0 | O17: 0 | P17: 0.001
A18: 3 | B18: 1000005 | C18: 体力 | D18: 1000006 | E18: 闯关体力：用于挑战关卡，每30分钟回复1点。 | F18: 0 | G18: 0 | H18: ="icon_"&A18 -> icon_3 | K18: 4 | L18: 0 | M18: 0 | N18: 0 | O18: 0 | P18: 1
A19: 4 | B19: 1000007 | C19: 活跃度 | D19: 1000008 | E19: 完成日常任务累积活跃度，领取每日、每周活跃礼包。 | F19: 0 | G19: 0 | H19: ="icon_"&A19 -> icon_4 | K19: 4 | L19: 0 | M19: 0 | N19: 0 | O19: 0 | P19: 1
A20: 5 | B20: 1000009 | C20: 经验 | D20: 1000010 | E20: 对局、闯关等途径可获得经验。每日可获取经验上限为<color=#fff442>15000</color>。 | F20: 0 | G20: 0 | H20: ="icon_"&A20 -> icon_5 | K20: 5 | L20: 0 | M20: 0 | N20: 0 | O20: 0 | P20: 1
A21: 6 | B21: 1100001 | C21: VIP经验 | D21: 1100002 | E21: 通过活跃活动可获得，用于提升VIP等级。 | F21: 0 | G21: 0 | H21: ="icon_"&A21 -> icon_6 | K21: 5 | L21: 0 | M21: 0 | N21: 0 | O21: 0 | P21: 1
A22: 7 | B22: 1100003 | C22: 活跃点 | D22: 1100004 | E22: 完成新手任务累计活跃点，换取终极大奖。 | F22: 0 | G22: 0 | H22: ="icon_"&A22 -> icon_7 | K22: 4 | L22: 0 | M22: 0 | N22: 0 | O22: 0 | P22: 1
A23: 8 | B23: 1100005 | C23: 活跃值 | D23: 1100006 | E23: 完成俱乐部任务累计活跃值，可用于俱乐部商店兑换物品 | F23: 0 | G23: 0 | H23: ="icon_"&A23 -> icon_8 | K23: 4 | L23: 0 | M23: 0 | N23: 0 | O23: 0
A24: 9 | B24: 1100007 | C24: 极限挑战币 | D24: 1100008 | E24: 完成极限挑战每日任务可获得极限挑战兑换币，可用于兑换商店兑换物品 | F24: 0 | G24: 0 | H24: ="icon_"&A24 -> icon_9 | K24: 4 | L24: 0 | M24: 0 | N24: 0 | O24: 0
A25: 10 | B25: 1100009 | C25: 积分 | D25: 1100010 | E25: 进行扭蛋可获得积分，可用于兑换积分商城内的物品 | F25: 0 | G25: 0 | H25: ="icon_"&A25 -> icon_10 | K25: 4 | L25: 0 | M25: 0 | N25: 0 | O25: 0
A26: 11 | B26: 1200001 | C26: 极限挑战次数 | D26: 1200002 | E26: 极限挑战消耗，随时间恢复 | F26: 0 | G26: 0 | H26: ="icon_"&A26 -> icon_11 | K26: 4 | L26: 0 | M26: 0 | N26: 0 | O26: 0
A27: 12 | B27: 1200003 | C27: 兑换券 | D27: 1200004 | E27: 对局、闯关、活跃等途径可获得球杆币。可用于兑换商店兑换永久球杆和培养材料。 | F27: 0 | G27: 0 | H27: ="icon_"&A27 -> icon_12 | K27: 4 | L27: 0 | M27: 0 | N27: 0 | O27: 0
A28: 13 | B28: 1200005 | C28: 强化币 | D28: 1200006 | E28: 对局、闯关、活跃等途径可获得球杆币。可用于球杆的升星、升阶。 | F28: 0 | G28: 0 | H28: ="icon_"&A28 -> icon_13 | K28: 4 | L28: 0 | M28: 0 | N28: 0 | O28: 0
A29: 14 | B29: 1200007 | C29: 钻石藏宝图 | D29: 1200008 | E29: 参与钻石宝藏寻宝可获得钻石藏宝图，可用于宝藏商店兑换永久球杆。 | F29: 0 | G29: 0 | H29: ="icon_"&A29 -> icon_14 | K29: 6 | L29: 0 | M29: 0 | N29: 0 | O29: 0
A30: 15 | B30: 1200009 | C30: 金币藏宝图 | D30: 1200010 | E30: 参与金币宝藏寻宝可获得金币藏宝图，可用于宝藏商店兑换永久球杆。 | F30: 0 | G30: 0 | H30: ="icon_"&A30 -> icon_15 | K30: 5 | L30: 0 | M30: 0 | N30: 0 | O30: 0
A31: 16 | B31: 1200011 | C31: 航海币 | D31: 1200012 | E31: 完成活动任务可获得航海币，参与航海探险收集永久球杆和其他大奖 | F31: 0 | G31: 0 | H31: ="icon_"&A34 -> icon_19 | K31: 4 | L31: 0 | M31: 0 | N31: 0 | O31: 0
A32: 17 | B32: 1200013 | C32: 通行证对局活跃度 | D32: 1200014 | E32: 通行证对局活跃度 | F32: 0 | G32: 0 | H32: ="icon_"&A32 -> icon_17 | K32: 4 | L32: 0 | M32: 0 | N32: 0 | O32: 0
A33: 18 | B33: 1200015 | C33: 通行证任务活跃度 | D33: 1200016 | E33: 通行证任务活跃度 | F33: 0 | G33: 0 | H33: ="icon_"&A33 -> icon_18 | K33: 4 | L33: 0 | M33: 0 | N33: 0 | O33: 0
A34: 19 | B34: 1200017 | C34: 免费 | D34: 1200018 | E34: 用于神秘商城中购买免费商品 | F34: 0 | G34: 0 | K34: 1 | L34: 0 | M34: 0 | N34: 0 | O34: 0
A35: 20 | B35: 1200019 | C35: 视频券 | D35: 1200020 | E35: 抵消一次视频广告 | F35: 8 | G35: 4 | H35: icon_20 | K35: 6 | L35: 10 | M35: 0 | N35: 0 | O35: 0
A36: 21 | B36: 1200021 | C36: 大喇叭 | D36: 1200022 | E36: 用于世界聊天置顶发言 | F36: 8 | G36: 3,64 | H36: icon_21 | K36: 4 | L36: 0 | M36: 0 | N36: 0 | O36: 0
A37: 22 | B37: 1200023 | C37: 苹果 | D37: 1200024 | E37: 用于欢乐果园兑换奖励 | F37: 0 | G37: 0 | H37: icon_22 | K37: 4 | L37: 0 | M37: 0 | N37: 0 | O37: 0
A38: 23 | B38: 1200025 | C38: 香蕉 | D38: 1200026 | E38: 用于欢乐果园兑换奖励 | F38: 0 | G38: 0 | H38: icon_23 | K38: 4 | L38: 0 | M38: 0 | N38: 0 | O38: 0
A39: 24 | B39: 1200027 | C39: 积分 | D39: 1200028 | E39: 用于积分商城兑换奖励 | F39: 0 | G39: 0 | H39: icon_24 | K39: 4 | L39: 0 | M39: 0 | N39: 0 | O39: 0
A40: 25 | B40: 1200029 | C40: 小喇叭 | D40: 1200030 | E40: 用户地域聊天置顶发言 | F40: 8 | G40: 3,69 | H40: icon_25 | K40: 3 | L40: 0 | M40: 0 | N40: 0 | O40: 0 | P40: 10
A41: 26 | B41: 1200031 | C41: 刮刮券 | D41: 1200032 | E41: 用于刮刮乐活动，刮奖获取永久球杆和其它奖励 | F41: 8 | G41: 3,70 | H41: icon_26 | K41: 3 | L41: 0 | M41: 0 | N41: 0 | O41: 0 | P41: 10
A42: 27 | B42: 1200033 | C42: A杆自选礼包 | D42: 1200034 | E42: 开启自选永久A级球杆 | F42: 25 | G42: 1 | H42: icon_27 | K42: 4 | L42: 12 | M42: 1000001 | N42: 2 | O42: 0
...

Sheet cue
A1: CONFIG_NAME | B1: cue | C1: 配置名, 如果没有这个字段, 则这个Sheet不会导出
A2: CONFIG_DESCRIPTION | B2: cue | C2: 可选, 配置文件描述.
A3: COLOR_COMMENT | B3: comment | C3: 注释背景颜色
A4: COLOR_COLUMN_INFO | B4: column_info
A5: RELATED_CONFIG | C5: 可选, 关联的表格
A6: TABLE_HEAD_LEN | B6: 4 | C6: 可选, 默认为3, 字段描述的长度.
A7: TABLE_PROPERTY
A8: TABLE_PROPERTY_RELATED
M9: 最终属性=初始属性+星级绝对值加成*(1+系数/100)
A11: 序号 | B11: 参考中文名 | C11: 球杆类型 | D11: 耐久度 | E11: 进球、拖尾特效 | F11: 瞄准线等级 | G11: 品质等级 | H11: 进阶球杆id | I11: 力度 | J11: 加塞 | K11: 瞄准 | L11: 魅力评分 | M11: =I11&"成长系数" -> 力度成长系数 | N11: =J11&"成长系数" -> 加塞成长系数 | O11: =K11&"成长系数" -> 瞄准成长系数 | P11: =L11&"成长系数" -> 魅力评分成长系数 | Q11: 专属升星材料 | R11: 专属进阶材料 | S11: 专属熟练度材料 | T11: 补偿碎片ID | U11: 补偿碎片 | V11: 球杆主属性 | W11: 满即预览按钮配置
A12: id | B12: name_ch | C12: type | D12: durability | E12: effect_id | F12: level_aim | G12: quality | H12: id_advanced | I12: force | J12: spin | K12: aim | L12: charm_value | M12: force_factor | N12: spin_factor | O12: aim_factor | P12: charm_value_factor | Q12: fir_material_rising | R12: fir_material_advanced | S12: fir_proficiency | T12: compensation | U12: count_comp | V12: cue_main | W12: button
A13: int32 | B13: string | C13: int32 | D13: int32 | E13: string | F13: int32 | G13: int32 | H13: int32 | I13: int32 | J13: int32 | K13: int32 | L13: int32 | M13: int32 | N13: int32 | O13: int32 | P13: int32 | Q13: int32 | R13: int32 | S13: int32 | T13: int32 | U13: int32 | V13: int32 | W13: list
A14: key,lua,pb,json | C14: lua,pb,json | D14: lua,pb,json | E14: lua,pb,json | F14: lua,pb,json | G14: lua,pb,json | H14: lua,pb,json | I14: lua,pb,json | J14: lua,pb,json | K14: lua,pb,json | L14: lua,pb,json | M14: lua,pb,json | N14: lua,pb,json | O14: lua,pb,json | P14: lua,pb,json | Q14: lua,pb,json | R14: lua,pb,json | S14: lua,pb,json | T14: lua,pb,json | U14: lua,pb,json | V14: lua,pb,json | W14: lua,pb,json | Y14: 获得品阶 | Z14: 补偿数量
B15: 0 | C15: 0 | D15: 0 | E15: , | F15: 1 | G15: 0 | H15: 0 | I15: 0 | J15: 0 | K15: 0 | L15: 0 | M15: 0 | N15: 0 | O15: 0 | P15: 0 | Q15: 0 | R15: 0 | S15: 0 | T15: 0 | U15: 0 | V15: 0 | W15: [] | Y15: C | Z15: 6
A16: 100001 | B16: 原木球杆 | C16: 1 | E16: , | F16: =IF(G16>3,2,1) -> 1 | G16: 2 | H16: =A17 -> 100002 | I16: 400 | J16: 400 | K16: 42 | L16: 1000 | M16: 0 | N16: 0 | O16: 0 | P16: 0 | Q16: 0 | R16: 510001 | T16: 510001 | U16: 6 | V16: 3 | Y16: B | Z16: 16
A17: 100002 | B17: 原木球杆 | C17: 1 | E17: , | F17: =IF(G17>3,2,1) -> 1 | G17: 3 | H17: =A18 -> 100003 | I17: 440 | J17: 440 | K17: 48 | L17: 3000 | M17: 0 | N17: 0 | O17: 0 | P17: 0 | Q17: 0 | R17: 510001 | T17: 510001 | U17: 16 | V17: 3 | Y17: A | Z17: 20
A18: 100003 | B18: 原木球杆 | C18: 1 | E18: , | F18: =IF(G18>3,2,1) -> 2 | G18: 4 | H18: 0 | I18: 485 | J18: 485 | K18: 55 | L18: 6000 | M18: 0 | N18: 0 | O18: 0 | P18: 0 | Q18: 0 | R18: 510001 | T18: 510001 | U18: 20 | V18: 3 | Y18: S | Z18: 100
A19: 100011 | B19: 地狱火焰 | C19: 1 | E19: , | F19: =IF(G19>3,2,1) -> 2 | G19: 4 | H19: 100012 | I19: 526 | J19: 490 | K19: 41 | L19: 6000 | M19: 100 | N19: 100 | O19: 100 | P19: 0 | Q19: 0 | R19: 510011 | T19: 510011 | U19: 20 | V19: 1 | Y19: SS | Z19: 200
A20: 100012 | B20: 地狱火焰 | C20: 1 | E20: , | F20: =IF(G20>3,2,1) -> 2 | G20: 5 | H20: 100013 | I20: 572 | J20: 540 | K20: 52 | L20: 10500 | M20: 100 | N20: 100 | O20: 100 | P20: 0 | Q20: 0 | R20: 510011 | T20: 510011 | U20: 100 | V20: 1 | Y20: SSS | Z20: 400
A21: 100013 | B21: 地狱火焰 | C21: 1 | F21: =IF(G21>3,2,1) -> 2 | G21: 6 | H21: 100014 | I21: 618 | J21: 590 | K21: 62 | L21: 15000 | M21: 100 | N21: 100 | O21: 100 | P21: 0 | Q21: 0 | R21: 510011 | T21: 510011 | U21: 200 | V21: 1
A22: 100014 | B22: 地狱火焰 | C22: 1 | F22: =IF(G22>3,2,1) -> 2 | G22: 7 | H22: 0 | I22: 666 | J22: 643 | K22: 72 | L22: 21000 | M22: 100 | N22: 100 | O22: 100 | P22: 0 | Q22: 0 | R22: 510011 | T22: 510011 | U22: 400 | V22: 1 | Y22: [2,61]
A23: 100018 | B23: 地狱火焰 | C23: 1 | E23: , | F23: =IF(G23>3,2,1) -> 2 | G23: 4 | H23: 100012 | I23: 526 | J23: 490 | K23: 41 | L23: 6000 | M23: 100 | N23: 100 | O23: 100 | P23: 0 | Q23: 0 | R23: 510011 | T23: 510011 | U23: 20 | V23: 1
A24: 100021 | B24: 国色天香 | C24: 1 | F24: =IF(G24>3,2,1) -> 2 | G24: 5 | H24: 100022 | I24: 541 | J24: 578 | K24: 52 | L24: 10500 | M24: 100 | N24: 100 | O24: 100 | P24: 0 | Q24: 0 | R24: 510021 | T24: 510021 | U24: 100 | V24: 2
A25: 100022 | B25: 国色天香 | C25: 1 | F25: =IF(G25>3,2,1) -> 2 | G25: 6 | H25: 100023 | I25: 590 | J25: 621 | K25: 62 | L25: 15000 | M25: 100 | N25: 100 | O25: 100 | P25: 0 | Q25: 0 | R25: 510021 | T25: 510021 | U25: 200 | V25: 2
A26: 100023 | B26: 国色天香 | C26: 1 | F26: =IF(G26>3,2,1) -> 2 | G26: 7 | H26: 0 | I26: 645 | J26: 665 | K26: 72 | L26: 21000 | M26: 100 | N26: 100 | O26: 100 | P26: 0 | Q26: 0 | R26: 510021 | T26: 510021 | U26: 400 | V26: 2
A27: 100027 | B27: 国色天香 | C27: 1 | F27: 2 | G27: 5 | H27: 100022 | I27: 541 | J27: 578 | K27: 52 | L27: 10500 | M27: 100 | N27: 100 | O27: 100 | P27: 0 | Q27: 0 | R27: 510021 | T27: 510021 | U27: 100 | V27: 2
A28: 100031 | B28: 白银球杆 | C28: 1 | F28: =IF(G28>3,2,1) -> 1 | G28: 2 | H28: 100032 | I28: 410 | J28: 400 | K28: 40 | L28: 1000 | M28: 0 | N28: 0 | O28: 0 | P28: 0 | Q28: 0 | R28: 510031 | T28: 510031 | U28: 6 | V28: 3
A29: 100032 | B29: 白银球杆 | C29: 1 | F29: =IF(G29>3,2,1) -> 1 | G29: 3 | H29: 100033 | I29: 450 | J29: 440 | K29: 46 | L29: 3000 | M29: 0 | N29: 0 | O29: 0 | P29: 0 | Q29: 0 | R29: 510031 | T29: 510031 | U29: 16 | V29: 3
A30: 100033 | B30: 白银球杆 | C30: 1 | F30: =IF(G30>3,2,1) -> 2 | G30: 4 | H30: 0 | I30: 495 | J30: 485 | K30: 52 | L30: 6000 | M30: 100 | N30: 100 | O30: 100 | P30: 0 | Q30: 0 | R30: 510031 | T30: 510031 | U30: 20 | V30: 3
A31: 100041 | B31: 骑士长枪 | C31: 1 | F31: =IF(G31>3,2,1) -> 2 | G31: 4 | H31: 100042 | I31: 495 | J31: 492 | K31: 52 | L31: 6000 | M31: 100 | N31: 100 | O31: 100 | P31: 0 | Q31: 0 | R31: 510041 | T31: 510041 | U31: 20 | V31: 3
A32: 100042 | B32: 骑士长枪 | C32: 1 | F32: =IF(G32>3,2,1) -> 2 | G32: 5 | H32: 100043 | I32: 546 | J32: 541 | K32: 64 | L32: 10500 | M32: 100 | N32: 100 | O32: 100 | P32: 0 | Q32: 0 | R32: 510041 | T32: 510041 | U32: 100 | V32: 3
A33: 100043 | B33: 骑士长枪 | C33: 1 | F33: =IF(G33>3,2,1) -> 2 | G33: 6 | H33: 100044 | I33: 592 | J33: 594 | K33: 74 | L33: 15000 | M33: 100 | N33: 100 | O33: 100 | P33: 0 | Q33: 0 | R33: 510041 | T33: 510041 | U33: 200 | V33: 3
A34: 100044 | B34: 骑士长枪 | C34: 1 | F34: =IF(G34>3,2,1) -> 2 | G34: 7 | H34: 0 | I34: 640 | J34: 641 | K34: 84 | L34: 21000 | M34: 100 | N34: 100 | O34: 100 | P34: 0 | Q34: 0 | R34: 510041 | T34: 510041 | U34: 400 | V34: 3
A35: 100048 | B35: 骑士长枪 | C35: 1 | F35: =IF(G35>3,2,1) -> 2 | G35: 4 | H35: 100042 | I35: 495 | J35: 492 | K35: 52 | L35: 6000 | M35: 100 | N35: 100 | O35: 100 | P35: 0 | Q35: 0 | R35: 510041 | T35: 510041 | U35: 20 | V35: 3
A36: 100051 | B36: 如鱼得水 | C36: 1 | F36: =IF(G36>3,2,1) -> 2 | G36: 5 | H36: 100052 | I36: 543 | J36: 538 | K36: 63 | L36: 10500 | M36: 100 | N36: 100 | O36: 100 | P36: 0 | Q36: 0 | R36: 510051 | T36: 510051 | U36: 100 | V36: 3
A37: 100052 | B37: 如鱼得水 | C37: 1 | F37: =IF(G37>3,2,1) -> 2 | G37: 6 | H37: 100053 | I37: 592 | J37: 584 | K37: 73 | L37: 15000 | M37: 100 | N37: 100 | O37: 100 | P37: 0 | Q37: 0 | R37: 510051 | T37: 510051 | U37: 200 | V37: 3
A38: 100053 | B38: 如鱼得水 | C38: 1 | F38: =IF(G38>3,2,1) -> 2 | G38: 7 | H38: 0 | I38: 644 | J38: 636 | K38: 83 | L38: 21000 | M38: 100 | N38: 100 | O38: 100 | P38: 0 | Q38: 0 | R38: 510051 | T38: 510051 | U38: 400 | V38: 3
A39: 100055 | B39: 如鱼得水 | C39: 1 | F39: 2 | G39: 4 | H39: 100051 | I39: 491 | J39: 486 | K39: 53 | L39: 6000 | M39: 100 | N39: 100 | O39: 100 | P39: 0 | Q39: 0 | R39: 510051 | T39: 510051 | U39: 20 | V39: 3
A40: 100061 | B40: 街头潮牌 | C40: 1 | F40: =IF(G40>3,2,1) -> 2 | G40: 4 | H40: 100062 | I40: 520 | J40: 489 | K40: 42 | L40: 6000 | M40: 100 | N40: 100 | O40: 100 | P40: 0 | Q40: 0 | R40: 510061 | T40: 510061 | U40: 20 | V40: 1
A41: 100062 | B41: 街头潮牌 | C41: 1 | F41: =IF(G41>3,2,1) -> 2 | G41: 5 | H41: 100063 | I41: 566 | J41: 540 | K41: 53 | L41: 10500 | M41: 100 | N41: 100 | O41: 100 | P41: 0 | Q41: 0 | R41: 510061 | T41: 510061 | U41: 100 | V41: 1
...

Sheet cue_level
A1: CONFIG_NAME | B1: cue_level | C1: 配置名, 如果没有这个字段, 则这个Sheet不会导出
A2: CONFIG_DESCRIPTION | B2: 球杆升级属性配置 | C2: 可选, 配置文件描述.
A3: COLOR_COMMENT | B3: comment | C3: 注释背景颜色
A4: COLOR_COLUMN_INFO | B4: column_info
A5: RELATED_CONFIG | C5: 可选, 关联的表格
A6: TABLE_HEAD_LEN | B6: 4 | C6: 可选, 默认为3, 字段描述的长度.
A7: TABLE_PROPERTY
A8: TABLE_PROPERTY_RELATED
A11: 品质 | B11: 星级 | C11: 升级类型 | D11: 力度绝对值 | E11: 加塞绝对值 | F11: 瞄准绝对值 | G11: 魅力评分绝对值 | H11: 材料1消耗数量 | I11: 通用材料 | J11: 材料2消耗数量 | K11: 熟练度消耗
A12: quality | B12: star | C12: upgrade_type | D12: force_ratio | E12: spin_ratio | F12: aim_ratio | G12: charm_value_ratio | H12: fir_material_count | I12: sec_material | J12: sec_material_count | K12: proficiency
A13: int32 | B13: int32 | C13: int32 | D13: int32 | E13: int32 | F13: int32 | G13: int32 | H13: int32 | I13: int32 | J13: int32 | K13: int32
A14: multikey,lua,pb,json | B14: multikey,lua,pb,json | C14: lua,pb,json | D14: lua,pb,json | E14: lua,pb,json | F14: lua,pb,json | G14: lua,pb,json | H14: lua,pb,json | I14: lua,pb,json | J14: lua,pb,json | K14: lua,pb,json
A15: 0 | B15: 0 | C15: 1 | D15: 0 | E15: 0 | F15: 0 | G15: 0 | H15: 0 | I15: 0 | J15: 0 | K15: 0
A16: 2 | B16: 0 | C16: 1 | D16: 0 | E16: 0 | F16: 0 | G16: 0 | H16: 5 | I16: 600001 | J16: 10 | K16: 30
A17: 2 | B17: 1 | C17: 1 | D17: 5 | E17: 5 | F17: 1 | G17: 50 | H17: 10 | I17: 600001 | J17: 12 | K17: 30
A18: 2 | B18: 2 | C18: 1 | D18: 10 | E18: 10 | F18: 2 | G18: 100 | H18: 15 | I18: 600001 | J18: 14 | K18: 30
A19: 2 | B19: 3 | C19: 1 | D19: 15 | E19: 15 | F19: 3 | G19: 150 | H19: 20 | I19: 600001 | J19: 16 | K19: 30
A20: 2 | B20: 4 | C20: 1 | D20: 20 | E20: 20 | F20: 4 | G20: 200 | H20: 25 | I20: 600001 | J20: 18 | K20: 30
A21: 2 | B21: 5 | C21: 2 | D21: 25 | E21: 25 | F21: 5 | G21: 250 | H21: 30 | I21: 600003 | J21: 50 | K21: 30
A22: 3 | B22: 0 | C22: 1 | D22: 0 | E22: 0 | F22: 0 | G22: 0 | H22: 35 | I22: 600001 | J22: 20 | K22: 200
A23: 3 | B23: 1 | C23: 1 | D23: 4 | E23: 4 | F23: 1 | G23: 100 | H23: 40 | I23: 600001 | J23: 24 | K23: 200
A24: 3 | B24: 2 | C24: 1 | D24: 8 | E24: 8 | F24: 2 | G24: 200 | H24: 45 | I24: 600001 | J24: 28 | K24: 200
A25: 3 | B25: 3 | C25: 1 | D25: 12 | E25: 12 | F25: 3 | G25: 300 | H25: 50 | I25: 600001 | J25: 32 | K25: 200
A26: 3 | B26: 4 | C26: 1 | D26: 16 | E26: 16 | F26: 4 | G26: 400 | H26: 55 | I26: 600001 | J26: 36 | K26: 200
... A57: 8 | B57: 5 | C57: 0 | D57: 50 | E57: 50 | F57: 10 | G57: 5000 | H57: 200 | I57: 0 | J57: 0 | K57: 2000

Sheet cue_attribute
A1: CONFIG_NAME | B1: cue_attribute | C1: 配置名, 如果没有这个字段, 则这个Sheet不会导出
A2: CONFIG_DESCRIPTION | B2: 球杆品质属性上限 | C2: 可选, 配置文件描述.
A3: COLOR_COMMENT | B3: comment | C3: 注释背景颜色
A4: COLOR_COLUMN_INFO | B4: column_info
A5: RELATED_CONFIG | C5: 可选, 关联的表格
A6: TABLE_HEAD_LEN | B6: 4 | C6: 可选, 默认为3, 字段描述的长度.
A7: TABLE_PROPERTY
A8: TABLE_PROPERTY_RELATED
A11: 品质 | B11: 力度最大值 | C11: 加塞最大值 | D11: 瞄准最大值 | E11: 魅力评分最大值
A12: quality | B12: force_max | C12: spin_max | D12: aim_max | E12: charm_max
A13: int32 | B13: int32 | C13: int32 | D13: int32 | E13: int32
A14: key,lua,pb,json | B14: lua,pb,json | C14: lua,pb,json | D14: lua,pb,json | E14: lua,pb,json
A15: 0 | B15: 0 | C15: 0 | D15: 0 | E15: 0
A16: 1 | B16: 400 | C16: 400 | D16: 30 | E16: 1000
A17: 2 | B17: 440 | C17: 440 | D17: 37 | E17: 3000
A18: 3 | B18: 485 | C18: 485 | D18: 45 | E18: 6000
A19: 4 | B19: 543 | C19: 543 | D19: 54 | E19: 10500
A20: 5 | B20: 594 | C20: 594 | D20: 64 | E20: 15000
A21: 6 | B21: 660 | C21: 660 | D21: 75 | E21: 21000
A22: 7 | B22: 700 | C22: 700 | D22: 94 | E22: 26000
A23: 8 | B23: 750 | C23: 750 | D23: 110 | E23: 55000

Sheet cue_experience
A1: CONFIG_NAME | B1: cue_experience | C1: 配置名, 如果没有这个字段, 则这个Sheet不会导出
A2: CONFIG_DESCRIPTION | B2: 球杆升级属性配置 | C2: 可选, 配置文件描述.
A3: COLOR_COMMENT | B3: comment | C3: 注释背景颜色
A4: COLOR_COLUMN_INFO | B4: column_info
A5: RELATED_CONFIG | C5: 可选, 关联的表格
A6: TABLE_HEAD_LEN | B6: 4 | C6: 可选, 默认为3, 字段描述的长度.
A7: TABLE_PROPERTY
A8: TABLE_PROPERTY_RELATED
A11: 体验球杆id | B11: 参考中文名 | C11: 对应球杆id | D11: 货币类型 | E11: 直售价格 | F11: 星级 | G11: 原价 | H11: 我要变强
A12: experience_id | B12: name_ch | C12: cue_id | D12: type_money | E12: price | F12: star | G12: ori_price | H12: strong
A13: int32 | B13: string | C13: int32 | D13: int32 | E13: int32 | F13: int32 | G13: int32 | H13: int32
A14: key,lua,pb,json | C14: lua,pb,json | D14: lua,pb,json | E14: lua,pb,json | F14: lua,pb,json | G14: lua,pb,json | H14: lua,pb,json
A15: 0 | B15: 0 | C15: 0 | D15: 0 | E15: 0 | F15: 5 | G15: 0 | H15: 0 | N15: 新球杆
A16: 120001 | B16: 原木球杆(体验球杆) | C16: 100003 | D16: 1 | E16: 588 | F16: 0 | G16: 1988 | J16: 188 | K16: 268 | L16: =J16/K16 -> 0.70149254 | N16: S | O16: 1288
A17: 120010 | B17: 地狱火焰 | C17: 100011 | D17: 1 | E17: 588 | F17: 0 | G17: 888 | H17: 1 | J17: 588 | K17: 888 | L17: =J17/K17 -> 0.66216216 | N17: SS | O17: 2488
A18: 120011 | B18: 地狱火焰 | C18: 100012 | D18: 1 | E18: 888 | F18: 0 | G18: 1988 | H18: 1 | J18: 988 | K18: =1988 -> 1988 | L18: =J18/K18 -> 0.49698189 | N18: SSS | O18: 3888
A19: 120012 | B19: 地狱火焰 | C19: 100013 | D19: 1 | E19: 1588 | F19: 0 | G19: 6888 | H19: 1 | J19: 2888 | K19: 6888 | L19: =J19/K19 -> 0.41927991
A20: 120013 | B20: 地狱火焰 | C20: 100014 | D20: 1 | E20: 2888 | F20: 0 | G20: 15888 | H20: 1 | J20: 5888 | K20: 15888 | L20: =J20/K20 -> 0.37059416
A21: 120021 | B21: 国色天香 | C21: 100021 | D21: 1 | E21: 888 | F21: 0 | G21: 1988 | H21: 1 | J21: 9888 | K21: 28888 | L21: =J21/K21 -> 0.34228745
A22: 120022 | B22: 国色天香 | C22: 100022 | D22: 1 | E22: 1588 | F22: 0 | G22: 6888 | H22: 1
A23: 120023 | B23: 国色天香 | C23: 100023 | D23: 1 | E23: 2888 | F23: 0 | G23: 15888 | H23: 1
A24: 120031 | B24: 白银球杆 | C24: 100033 | D24: 1 | E24: 588 | F24: 0 | G24: 888 | H24: 1 | J24: 588 | K24: 0 | L24: 888
A25: 120041 | B25: 骑士长枪 | C25: 100042 | D25: 1 | E25: 888 | F25: 0 | G25: 1988 | H25: 1 | J25: 888 | K25: 0 | L25: 1988
A26: 120042 | B26: 骑士长枪 | C26: 100043 | D26: 1 | E26: 1588 | F26: 0 | G26: 6888 | H26: 1
A27: 120043 | B27: 骑士长枪 | C27: 100044 | D27: 1 | E27: 2888 | F27: 0 | G27: 15888 | H27: 1
A28: 120050 | B28: 如鱼得水 | C28: 100055 | D28: 1 | E28: 588 | F28: 0 | G28: 888 | H28: 1
A29: 120051 | B29: 如鱼得水 | C29: 100051 | D29: 1 | E29: 888 | F29: 0 | G29: 1988 | H29: 1
A30: 120052 | B30: 如鱼得水 | C30: 100052 | D30: 1 | E30: 1588 | F30: 0 | G30: 6888 | H30: 1
A31: 120053 | B31: 如鱼得水 | C31: 100053 | D31: 1 | E31: 2888 | F31: 0 | G31: 15888 | H31: 1
A32: 120060 | B32: 街头潮牌 | C32: 100061 | D32: 1 | E32: 588 | F32: 0 | G32: 888 | H32: 1
A33: 120061 | B33: 街头潮牌 | C33: 100062 | D33: 1 | E33: 1588 | F33: 0 | G33: 1988 | H33: 1
A34: 120062 | B34: 街头潮牌 | C34: 100063 | D34: 1 | E34: 2888 | F34: 0 | G34: 6888 | H34: 1
A35: 120071 | B35: 紫金葫芦 | C35: 100071 | D35: 1 | E35: 888 | F35: 0 | G35: 1988 | H35: 1
A36: 120072 | B36: 紫金葫芦 | C36: 100072 | D36: 1 | E36: 1588 | F36: 0 | G36: 6888 | H36: 1
A37: 120073 | B37: 紫金葫芦 | C37: 100073 | D37: 1 | E37: 2888 | F37: 0 | G37: 15888 | H37: 1
... A55: 120133 | B55: 圣诞糖果 | C55: 100133 | D55: 1 | E55: 2888 | F55: 0 | G55: 15888 | H55: 1
A56: 120141 | B56: 圣诞树 | C56: 100141 | D56: 1 | E56: 888 | F56: 0 | G56: 1988
A57: 120142 | B57: 圣诞树 | C57: 100142 | D57: 1 | E57: 1588 | F57: 0 | G57: 6888
A58: 120143 | B58: 圣诞树 | C58: 100143 | D58: 1 | E58: 2888 | F58: 0 | G58: 15888
A59: 120147 | B59: 圣诞树 | C59: 100147 | D59: 1 | E59: 588 | F59: 0 | G59: 888
...

Sheet clothes
A1: CONFIG_NAME | B1: clothes | C1: 配置名, 如果没有这个字段, 则这个Sheet不会导出
A2: CONFIG_DESCRIPTION | B2: 服装属性配置 | C2: 可选, 配置文件描述.
A3: COLOR_COMMENT | B3: comment | C3: 注释背景颜色
A4: COLOR_COLUMN_INFO | B4: column_info
A5: RELATED_CONFIG | C5: 可选, 关联的表格
A6: TABLE_HEAD_LEN | B6: 4 | C6: 可选, 默认为3, 字段描述的长度.
A7: TABLE_PROPERTY
A8: TABLE_PROPERTY_RELATED
A11: 序号 | B11: 参考中文名 | C11: 魅力评分 | D11: 补偿物品ID | E11: 补偿数量
A12: id | B12: name_ch | C12: charm_value | D12: compensation | E12: count_comp
A13: int32 | B13: string | C13: int32 | D13: int32 | E13: int32
A14: key,lua,pb,json | C14: lua,pb,json | D14: lua,pb,json | E14: lua,pb,json
B15: 0 | C15: 0 | D15: 0 | E15: 0
A16: 200001 | B16: 经典服饰 | C16: 1000 | D16: 1 | E16: 1
A17: 200002 | B17: 街头潮牌 | C17: 2000 | D17: 1 | E17: 1
A18: 200003 | B18: 夏日派对 | C18: 6000 | D18: 1 | E18: 1
A19: 200004 | B19: 牛仔很忙 | C19: 4000 | D19: 1 | E19: 1
A20: 200005 | B20: 超级巨星 | C20: 4000 | D20: 1 | E20: 1
A21: 200006 | B21: 黑色礼服 | C21: 2000 | D21: 1 | E21: 1
A22: 200007 | B22: 虎啸风生 | C22: 6000 | D22: 1 | E22: 1
A23: 200008 | B23: 关羽 | C23: 10000 | D23: 1 | E23: 1
A24: 200009 | B24: 关银屏 | C24: 10000 | D24: 1 | E24: 1
A25: 200010 | B25: 瑞兔锦衣 | C25: 6000 | D25: 1 | E25: 1
A26: 200011 | B26: 纯白爱恋 | C26: 6000 | D26: 1 | E26: 1
A27: 200012 | B27: 梦幻学园 | C27: 6000 | D27: 1 | E27: 1
... A32: 200017 | B32: 蒸汽朋克 | C32: 6000 | D32: 1 | E32: 1
A33: 200018 | C33: 10000 | D33: 1 | E33: 1
A34: 200020 | B34: 齐天大圣 | C34: 10000 | D34: 1 | E34: 1
A35: 200021 | B35: 紫霞仙子 | C35: 10000 | D35: 1 | E35: 1
A36: 200022 | B36: 龙腾盛世 | C36: 12000 | D36: 1 | E36: 1
A37: 200023 | C37: 12000 | D37: 1 | E37: 1

Sheet quality_price
A1: CONFIG_NAME | B1: quality_price | C1: 配置名, 如果没有这个字段, 则这个Sheet不会导出
A2: CONFIG_DESCRIPTION | B2: 球杆品质价位配置 | C2: 可选, 配置文件描述.
A3: COLOR_COMMENT | B3: comment | C3: 注释背景颜色
A4: COLOR_COLUMN_INFO | B4: column_info
A5: RELATED_CONFIG | C5: 可选, 关联的表格
A6: TABLE_HEAD_LEN | B6: 4 | C6: 可选, 默认为3, 字段描述的长度.
A7: TABLE_PROPERTY
A8: TABLE_PROPERTY_RELATED
A11: 品质id | B11: 参考中文名 | C11: 货币类型 | D11: 直售价格 | E11: 星级 | F11: 原价
A12: id | B12: name_ch | C12: type_money | D12: price | E12: star | F12: ori_price
A13: int32 | B13: string | C13: int32 | D13: int32 | E13: int32 | F13: int32
A14: key,lua,pb,json | C14: lua,pb,json | D14: lua,pb,json | E14: lua,pb,json | F14: lua,pb,json
A15: 0 | B15: 0 | C15: 0 | D15: 0 | E15: 5 | F15: 0
A16: 4 | B16: A级品质球杆 | C16: 1 | D16: 588 | E16: 5 | F16: 888
A17: 5 | B17: S级品质球杆 | C17: 1 | D17: 1088 | E17: 5 | F17: 1988
A18: 6 | B18: SS级品质球杆 | C18: 1 | D18: 2088 | E18: 5 | F18: 6888
A19: 7 | B19: SSS级品质球杆 | C19: 1 | D19: 3888 | E19: 5 | F19: 15888

Sheet combination
A1: CONFIG_NAME | B1: combination | C1: 配置名, 如果没有这个字段, 则这个Sheet不会导出
A2: CONFIG_DESCRIPTION | B2: 合成对应配置 | C2: 可选, 配置文件描述.
A3: COLOR_COMMENT | B3: comment | C3: 注释背景颜色
A4: COLOR_COLUMN_INFO | B4: column_info
A5: RELATED_CONFIG | C5: 可选, 关联的表格
A6: TABLE_HEAD_LEN | B6: 4 | C6: 可选, 默认为3, 字段描述的长度.
A7: TABLE_PROPERTY
A8: TABLE_PROPERTY_RELATED
A11: 待合成物品序号 | B11: 参考中文名 | C11: 消耗碎片序号 | D11: 合成消耗数量 | E11: 可合成性别
A12: com_id | B12: name_ch | C12: piece_id | D12: count | E12: sex_can
A13: int32 | B13: string | C13: int32 | D13: string | E13: int32
A14: key,lua,pb,json | C14: lua,pb,json | D14: lua,pb,json | E14: lua,pb,json | L14: 原配置 | M14: 原配置 | N14: 原配置 | O14: 原配置 | P14: 原配置
B15: 0 | C15: 0 | D15: [] | E15: 0 | F15: 等级 | G15: 备注
A16: 100001 | B16: 原木球杆 | C16: 510001 | D16: [[30,0]] | E16: 0 | F16: C | I16: C | L16: 100001 | M16: 原木球杆 | N16: 510001 | O16: [[30,0]] | P16: 0
A17: 100011 | B17: 地狱火焰 | C17: 510011 | D17: [[200,0]] | E17: 0 | F17: A | I17: B | L17: 100011 | M17: 地狱火焰 | N17: 510011 | O17: [[200,0]] | P17: 0
A18: 100013 | B18: 地狱火焰 | C18: 510011 | D18: [[1000,0]] | F18: SS | G18: SS起步 | I18: A | L18: 100021 | M18: 国色天香 | N18: 510021 | O18: [[100,0]] | P18: 0
A19: 100021 | B19: 国色天香 | C19: 510021 | D19: [[500,0]] | E19: 0 | F19: S | G19: S级起步 | I19: S | L19: 100031 | M19: 白银球杆 | N19: 510031 | O19: [[30,0]] | P19: 0
A20: 100031 | B20: 白银球杆 | C20: 510031 | D20: [[30,0]] | E20: 0 | F20: C | G20: C级起步 | I20: SS | L20: 100041 | M20: 骑士长枪 | N20: 510041 | O20: [[50,0]] | P20: 0
A21: 100041 | B21: 骑士长枪 | C21: 510041 | D21: [[200,0]] | E21: 0 | F21: A | G21: A级起步 | I21: SSS | L21: 100051 | M21: 如鱼得水 | N21: 510051 | O21: [[100,0]] | P21: 0
A22: 100051 | B22: 如鱼得水 | C22: 510051 | D22: [[500,0]] | E22: 0 | F22: S | G22: A级起步 | L22: 100055 | M22: 如鱼得水 | N22: 510051 | O22: [[100,0]] | P22: 0
A23: 100055 | B23: 如鱼得水 | C23: 510051 | D23: [[100,0]] | E23: 0 | F23: A | G23: A级起步 | L23: 100061 | M23: 街头潮牌 | N23: 510061 | O23: [[50,0]] | P23: 0
A24: 100061 | B24: 街头潮牌 | C24: 510061 | D24: [[200,0]] | E24: 0 | F24: A | G24: A级起步 | L24: 100071 | M24: 紫金葫芦 | N24: 510071 | O24: [[100,0]] | P24: 0
A25: 100071 | B25: 紫金葫芦 | C25: 510071 | D25: [[500,0]] | E25: 0 | F25: S | G25: S级起步 | L25: 100081 | M25: 黑色琴键 | N25: 510081 | O25: [[100,0]] | P25: 0
A26: 100081 | B26: 黑色琴键 | C26: 510081 | D26: [[500,0]] | E26: 0 | F26: S | G26: S级起步 | L26: 100091 | M26: 电音吉他S | N26: 510091 | O26: [[100,0]] | P26: 0
A27: 100091 | B27: 电音吉他S | C27: 510091 | D27: [[500,0]] | E27: 0 | F27: S | G27: S级起步 | L27: 100101 | M27: 台球麦霸 | N27: 510101 | O27: [[100,0]] | P27: 0
A28: 100101 | B28: 台球麦霸 | C28: 510101 | D28: [[500,0]] | E28: 0 | F28: S | G28: S级起步 | L28: 100111 | M28: 喵星物语 | N28: 510111 | O28: [[100,0]] | P28: 0
A29: 100114 | B29: 喵星物语 | C29: 510111 | D29: [[500,0]] | E29: 0 | F29: S | G29: S级起步 | L29: 100121 | M29: 夏日海滩 | N29: 510121 | O29: [[100,0]] | P29: 0
A30: 100121 | B30: 夏日海滩 | C30: 510121 | D30: [[500,0]] | E30: 0 | F30: S | G30: S级起步 | L30: 100131 | M30: 圣诞糖果 | N30: 510131 | O30: [[100,0]] | P30: 0
A31: 100131 | B31: 圣诞糖果 | C31: 510131 | D31: [[500,0]] | E31: 0 | F31: S | G31: S级起步 | L31: 100141 | M31: 圣诞树 | N31: 510141 | O31: [[100,0]] | P31: 0
A32: 100141 | B32: 圣诞树 | C32: 510141 | D32: [[500,0]] | E32: 0 | F32: S | G32: S级起步 | L32: 100151 | M32: 黄铜球杆 | N32: 510151 | O32: [[30,0]] | P32: 0
A33: 100151 | B33: 黄铜球杆 | C33: 510151 | D33: [[30,0]] | E33: 0 | F33: C | G33: C级起步 | L33: 100161 | M33: 梅花三弄 | N33: 510161 | O33: [[50,0]] | P33: 0
... A37: 100191 | B37: 台球达人 | C37: 510191 | D37: [[80,0]] | E37: 0 | F37: B | G37: B级起步 | L37: 100201 | M37: 雄鹰权杖 | N37: 510201 | O37: [[100,0]] | P37: 0
A38: 100201 | B38: 雄鹰权杖 | C38: 510201 | D38: [[200,0]] | E38: 0 | F38: S | G38: S级起步
A39: 100221 | B39: 双龙戏珠 | C39: 510221 | D39: [[200,0]] | F39: A | G39: A级起步
A40: 100232 | B40: 流光宝石 | C40: 510231 | D40: [[500,0]] | E40: 0 | F40: S
A41: 100240 | B41: 枫叶 | C41: 510241 | D41: [[80,0]] | E41: 0 | F41: B
A42: 100241 | B42: 枫叶 | C42: 510241 | D42: [[200,0]] | E42: 0
A43: 100251 | B43: 劳动光荣 | C43: 510251 | D43: [[80,0]]
A44: 100261 | B44: 楠木球杆 | C44: 510261 | D44: [[30,0]] | E44: 0 | F44: c | G44: C级起步
A45: 100271 | B45: 智慧权杖 | C45: 510271 | D45: [[30,0]] | E45: 0 | F45: C | G45: C级起步
...

Sheet cue_table
A1: CONFIG_NAME | B1: cue_table | C1: 配置名, 如果没有这个字段, 则这个Sheet不会导出
A2: CONFIG_DESCRIPTION | B2: 球桌补偿配置 | C2: 可选, 配置文件描述.
A3: COLOR_COMMENT | B3: comment | C3: 注释背景颜色
A4: COLOR_COLUMN_INFO | B4: column_info
A5: RELATED_CONFIG | C5: 可选, 关联的表格
A6: TABLE_HEAD_LEN | B6: 4 | C6: 可选, 默认为3, 字段描述的长度.
A7: TABLE_PROPERTY
A8: TABLE_PROPERTY_RELATED
A11: 序号 | B11: 参考中文名 | C11: 魅力评分 | D11: 球桌详情图 | E11: 补偿物品ID | F11: 补偿数量
A12: id | B12: name_ch | C12: charm_value | D12: table_picture | E12: compensation | F12: count_comp
A13: int32 | B13: string | C13: int32 | D13: string | E13: int32 | F13: int32
A14: key,lua,pb,json | C14: lua,pb,json | D14: lua,pb,json | E14: lua,pb,json | F14: lua,pb,json
B15: 0 | C15: 0 | D15: picture_1 | E15: 0 | F15: 0
A16: 300001 | B16: =VLOOKUP(A16,item!A:C,3,FALSE) -> 靛蓝球桌 | C16: 1000 | D16: picture_300001 | E16: 1 | F16: 1
A17: 300002 | B17: =VLOOKUP(A17,item!A:C,3,FALSE) -> 黛绿球桌 | C17: 1000 | D17: picture_300002 | E17: 1 | F17: 1
A18: 300003 | B18: =VLOOKUP(A18,item!A:C,3,FALSE) -> 暗红球桌 | C18: 1200 | D18: picture_300003 | E18: 1 | F18: 1
A19: 300004 | B19: 暖橘球桌 | C19: 1200 | D19: picture_300004 | E19: 1 | F19: 1
A20: 300005 | B20: 炫紫球桌 | C20: 1200 | D20: picture_300005 | E20: 1 | F20: 1
A21: 300006 | B21: 西瓜球桌 | C21: 3000 | D21: picture_300006 | E21: 1 | F21: 2
A22: 300007 | B22: 黑金科技 | C22: 5000 | D22: picture_300007 | E22: 1 | F22: 10
A23: 300008 | B23: 水晶之恋 | C23: 3000 | D23: picture_300008 | E23: 1 | F23: 2
A24: 300009 | B24: 动力驱动 | C24: 5000 | D24: picture_300009 | E24: 1 | F24: 10
A25: 300010 | B25: 繁星点点 | C25: 5000 | D25: picture_300010 | E25: 1 | F25: 10
A26: 300011 | B26: 机械齿轮 | C26: 5000 | D26: picture_300011 | E26: 1 | F26: 10
A27: 300012 | B27: 喵星物语 | C27: 5000 | D27: picture_300012 | E27: 1 | F27: 10
A28: 300013 | B28: 玛雅文明 | C28: 5000 | D28: picture_300013 | E28: 1 | F28: 10
A29: 300014 | B29: 国色天香 | C29: 5000 | D29: picture_300014 | E29: 1 | F29: 10
A30: 300015 | B30: 棒棒糖 | C30: 5000 | D30: picture_300015 | E30: 1 | F30: 10
... A32: 300017 | B32: 骑士之誓 | C32: 5000 | D32: picture_300017 | E32: 1 | F32: 10
A33: 300018 | C33: 5000 | D33: picture_300018 | E33: 1 | F33: 10
A34: 300019 | B34: 虎虎生威 | C34: 5000 | D34: picture_300019 | E34: 1 | F34: 10
A35: 300020 | B35: 战场球桌 | C35: 10000 | D35: picture_300020
A36: 300021 | B36: 绿茵足场 | C36: 8000 | D36: picture_300021 | E36: 1 | F36: 10
A37: 300022 | B37: 圣诞球桌 | C37: 8000 | D37: picture_300022 | E37: 1 | F37: 10
A38: 300023 | B38: 新春球桌 | C38: 8000 | D38: picture_300023
A39: 300024 | B39: 真爱至上 | C39: 8000 | D39: picture_300024
A40: 300025 | B40: 校园生活 | C40: 8000 | D40: picture_300025
A41: 300026 | B41: 劳动先锋 | C41: 8000 | D41: picture_300026 | E41: 1 | F41: 10
A42: 300027 | B42: 机械动力 | C42: 8000 | D42: picture_300027 | E42: 1 | F42: 10
A43: 300028 | B43: 端午球桌 | C43: 8000 | D43: picture_300028 | E43: 1 | F43: 10

Sheet head
A1: CONFIG_NAME | B1: head | C1: 配置名, 如果没有这个字段, 则这个Sheet不会导出
A2: CONFIG_DESCRIPTION | B2: 头像、头像框配置表 | C2: 可选, 配置文件描述.
A3: COLOR_COMMENT | B3: comment | C3: 注释背景颜色
A4: COLOR_COLUMN_INFO | B4: column_info
A5: RELATED_CONFIG | C5: 可选, 关联的表格
A6: TABLE_HEAD_LEN | B6: 4 | C6: 可选, 默认为3, 字段描述的长度.
A7: TABLE_PROPERTY
A8: TABLE_PROPERTY_RELATED
A11: 序号 | B11: 显示分类 | C11: 显示分类 | D11: 是否初始拥有 | E11: 解锁条件id | F11: 条件解释字段 | G11: 条件语言序号 | H11: 参考中文名 | I11: 获得方式跳转 | J11: 魅力评分 | K11: 显示顺序
A12: item_id | B12: show | C12: type_show | D12: have_If | E12: condition | F12: field | G12: name | H12: name_ch | I12: link | J12: charm_value | K12: order
A13: int32 | B13: int32 | C13: int32 | D13: int32 | E13: int32 | F13: string | G13: int32 | H13: string | I13: int32 | J13: int32 | K13: int32
A14: key,lua,pb,json | B14: lua,pb,json | C14: lua,pb,json | D14: lua,pb,json | E14: lua,pb,json | F14: lua,pb,json | G14: lua,pb,json | H14: vb | I14: lua,pb,json | J14: lua,pb,json | K14: lua,pb,json
B15: 2 | C15: 0 | D15: 0 | E15: 0 | F15: 0 | G15: 0 | I15: 0 | J15: 0 | K15: 0
A16: 800000 | B16: 2 | C16: 1 | D16: 1 | E16: 0 | F16: 0 | G16: 8000003 | H16: 无解锁条件 | I16: 0 | J16: 0
A17: 800001 | B17: 2 | C17: 1 | D17: 1 | E17: 0 | F17: 0 | G17: 8000013 | H17: 无解锁条件 | I17: 0 | J17: 0
A18: 800002 | B18: 2 | C18: 1 | D18: 1 | E18: 0 | F18: 0 | G18: 8000023 | H18: 无解锁条件 | I18: 0 | J18: 0
A19: 800003 | B19: 2 | C19: 1 | D19: 1 | E19: 0 | F19: 0 | G19: 8000033 | H19: 无解锁条件 | I19: 0 | J19: 0
A20: 800004 | B20: 2 | C20: 1 | D20: 1 | E20: 0 | F20: 0 | G20: 8000043 | H20: 无解锁条件 | I20: 0 | J20: 0
A21: 800005 | B21: 2 | C21: 1 | D21: 1 | E21: 0 | F21: 0 | G21: 8000053 | H21: 无解锁条件 | I21: 0 | J21: 0
A22: 800006 | B22: 2 | C22: 1 | D22: 1 | E22: 0 | F22: 0 | G22: 8000063 | H22: 无解锁条件 | I22: 0 | J22: 0
A23: 800007 | B23: 1 | C23: 1 | D23: 1 | E23: 3 | F23: 1,200002 | G23: 8000073 | H23: 获得首充服装-街头潮牌后解锁 | I23: 12 | J23: 0
A24: 800008 | B24: 1 | C24: 1 | D24: 1 | E24: 3 | F24: 1,200002 | G24: 8000083 | H24: 获得首充服装-街头潮牌后解锁 | I24: 12 | J24: 0
A25: 800009 | B25: 2 | C25: 1 | D25: 2 | E25: 0 | F25: 0 | G25: 8000093 | H25: 无解锁条件 | I25: 0 | J25: 0
A26: 800010 | B26: 2 | C26: 1 | D26: 3 | E26: 0 | F26: 0 | G26: 8000103 | H26: 无解锁条件 | I26: 0 | J26: 0
A27: 800011 | B27: 2 | C27: 1 | D27: 4 | E27: 0 | F27: 0 | G27: 8000113 | H27: 无解锁条件 | I27: 0 | J27: 0
A28: 800013 | B28: 1 | C28: 1 | D28: 0 | E28: 8 | F28: 0 | G28: 8000133 | H28: 玲珑专属活动获得 | I28: 0 | J28: 0
A29: 800014 | B29: 1 | C29: 1 | D29: 0 | E29: 8 | F29: 0 | G29: 8000143 | H29: 玲珑专属活动获得 | I29: 0 | J29: 0
A30: 800015 | B30: 1 | C30: 1 | D30: 0 | E30: 8 | F30: 0 | G30: 8000153 | H30: 绿茵专属活动获得 | I30: 0 | J30: 0
A31: 800016 | B31: 1 | C31: 1 | D31: 0 | E31: 8 | F31: 0 | G31: 8000163 | H31: 无解锁条件 | I31: 0 | J31: 0
A32: 800017 | B32: 1 | C32: 1 | D32: 0 | E32: 8 | F32: 0 | G32: 8000173 | H32: 无解锁条件 | I32: 0 | J32: 0
A33: 800018 | B33: 1 | C33: 1 | D33: 0 | E33: 8 | F33: 0 | G33: 8000183 | H33: 无解锁条件 | I33: 0 | J33: 0
A34: 800019 | B34: 1 | C34: 1 | D34: 0 | E34: 8 | F34: 0 | G34: 8000193 | H34: 无解锁条件 | I34: 0 | J34: 0
A35: 800020 | B35: 1 | C35: 1 | D35: 0 | E35: 8 | F35: 0 | G35: 8000203 | H35: 无解锁条件 | I35: 0 | J35: 0
A36: 800021 | B36: 1 | C36: 1 | D36: 0 | E36: 8 | F36: 0 | G36: 8000213 | H36: 无解锁条件 | I36: 0 | J36: 0
... A49: 800035 | B49: 1 | C49: 1 | D49: 0 | E49: 8 | F49: 0 | G49: 8000353 | H49: 限时夺宝活动获得 | I49: 0 | J49: 0
A50: 810001 | B50: 1 | C50: 2 | D50: 1 | E50: 0 | F50: 0 | G50: 8100013 | H50: 无解锁条件 | I50: 0 | J50: 0 | K50: 1
A51: 810002 | B51: 1 | C51: 2 | D51: 1 | E51: 1 | F51: 30 | G51: 8100023 | H51: 账号等级达到<color=#FF767A>30</color>级 | I51: 2 | J51: 0 | K51: 6
A52: 810003 | B52: 1 | C52: 2 | D52: 1 | E52: 2 | F52: 1 | G52: 8100033 | H52: VIP等级达到<color=#FF767A>1</color> | I52: 16 | J52: 0 | K52: 7
A53: 810004 | B53: 1 | C53: 2 | D53: 1 | E53: 2 | F53: 2 | G53: 8100043 | H53: VIP等级达到<color=#FF767A>2</color> | I53: 16 | J53: 0 | K53: 8
A54: 810005 | B54: 1 | C54: 2 | D54: 1 | E54: 2 | F54: 3 | G54: 8100053 | H54: VIP等级达到<color=#FF767A>3</color> | I54: 16 | J54: 0 | K54: 9
...

Sheet direct_purchase
A1: CONFIG_NAME | B1: direct_purchase | C1: 配置名, 如果没有这个字段, 则这个Sheet不会导出
A2: CONFIG_DESCRIPTION | B2: 道具直购参考价格表 | C2: 可选, 配置文件描述.
A3: COLOR_COMMENT | B3: comment | C3: 注释背景颜色
A4: COLOR_COLUMN_INFO | B4: column_info
A5: RELATED_CONFIG | C5: 可选, 关联的表格
A6: TABLE_HEAD_LEN | B6: 4 | C6: 可选, 默认为3, 字段描述的长度.
A7: TABLE_PROPERTY
A8: TABLE_PROPERTY_RELATED
A11: 物品 | B11: 参考中文名 | C11: 价格
A12: id | B12: name_ch | C12: price
A13: int32 | B13: string | C13: int32
A14: key,lua,pb,json | B14: vb | C14: lua,pb,json
A15: 0 | B15: 0 | C15: 0
A16: 600001 | B16: 升星木 | C16: 5
A17: 13 | B17: 强化币 | C17: 1
A18: 600003 | B18: C级升阶木 | C18: 1
A19: 600004 | B19: B级升阶木 | C19: 2
A20: 600005 | B20: A级升阶木 | C20: 10
A21: 600006 | B21: S级升阶木 | C21: 20
A22: 600007 | B22: SS级升阶木 | C22: 40

Sheet cue_effect
A1: CONFIG_NAME | B1: cue_effect | C1: 配置名, 如果没有这个字段, 则这个Sheet不会导出
A2: CONFIG_DESCRIPTION | B2: Z杆特效表 | C2: 可选, 配置文件描述.
A3: COLOR_COMMENT | B3: comment | C3: 注释背景颜色
A4: COLOR_COLUMN_INFO | B4: column_info
A5: RELATED_CONFIG | C5: 可选, 关联的表格
A6: TABLE_HEAD_LEN | B6: 4 | C6: 可选, 默认为3, 字段描述的长度.
A7: TABLE_PROPERTY
A8: TABLE_PROPERTY_RELATED
A11: 球杆id | B11: 备注 | C11: 特效 | D11: 显示区域宽高 | E11: 显示区域锚点 | F11: 显示区域坐标
A12: id | C12: effect | D12: size | E12: pivot | F12: pos
A13: int32 | C13: string | D13: string | E13: string | F13: string
A14: key,lua,pb,json | C14: lua,pb,json | D14: lua,pb,json | E14: lua,pb,json | F14: lua,pb,json
C15: 0 | D15: 0 | E15: 0 | F15: 0
A16: 100334 | C16: 1,2,3 | D16: 128,450 | E16: 64,450 | F16: 64,450
A17: 100354 | C17: 4,5,6 | D17: 300,128 | E17: 300,64 | F17: 300,64
A18: 101314 | C18: 7,8,9 | D18: 150,380 | E18: 75,380 | F18: 75,450
A19: 101434 | C19: 10,11,12 | D19: 300,128 | E19: 300,64 | F19: 300,64
A20: 140334 | C20: 1,2,3 | D20: 128,450 | E20: 64,450 | F20: 64,450
A21: 140354 | C21: 4,5,6 | D21: 300,128 | E21: 300,64 | F21: 300,64
A22: 141314 | C22: 7,8,9 | D22: 150,380 | E22: 75,380 | F22: 75,450
A23: 101444 | C23: 13,14,15 | D23: 150,320 | E23: 75,320 | F23: 361,404
A24: 101484 | C24: 16,17,18,19 | D24: 512,256 | E24: 512,128 | F24: 364,404

Sheet effect
A1: CONFIG_NAME | B1: effect | C1: 配置名, 如果没有这个字段, 则这个Sheet不会导出
A2: CONFIG_DESCRIPTION | B2: 球杆特效资源表 | C2: 可选, 配置文件描述.
A3: COLOR_COMMENT | B3: comment | C3: 注释背景颜色
A4: COLOR_COLUMN_INFO | B4: column_info
A5: RELATED_CONFIG | C5: 可选, 关联的表格
A6: TABLE_HEAD_LEN | B6: 4 | C6: 可选, 默认为3, 字段描述的长度.
A7: TABLE_PROPERTY
A8: TABLE_PROPERTY_RELATED
A11: 特效id | B11: 备注 | C11: 特效名称 | D11: 特效宽高 | E11: 特效锚点 | F11: 特效坐标 | G11: 特效缩放 | H11: 特效旋转角度
A12: id | C12: name | D12: size | E12: pivot | F12: pos | G12: scale | H12: rotation
A13: int32 | C13: string | D13: string | E13: string | F13: string | G13: string | H13: int32
A14: key,lua,pb,json | C14: lua,pb,json | D14: lua,pb,json | E14: lua,pb,json | F14: lua,pb,json | G14: lua,pb,json | H14: lua,pb,json
C15: 0 | D15: 0 | E15: 0 | F15: 0 | G15: 0 | H15: 0
A16: 1 | C16: 100333_Batting_cue_fx | D16: 128,450 | E16: 64,450 | F16: 64,450 | G16: 1,1
A17: 2 | C17: 100333_Batting_fx | D17: 280,280 | E17: 140,140 | F17: 280,280 | G17: 2,2
A18: 3 | C18: 100333_Batting_Hit_fx | D18: 278,278 | E18: 139,139 | F18: 450,450 | G18: 2,2
A19: 4 | C19: 100353_Batting_cue_fx | D19: 150,380 | E19: 75,0 | F19: 300,64 | G19: 1,1 | H19: 120
A20: 5 | C20: 100353_Batting_cue_fx | D20: 150,380 | E20: 75,0 | F20: 300,64 | G20: 1,1 | H20: 60
A21: 6 | C21: 100353_Batting_Hit_fx | D21: 400,300 | E21: 139,139 | F21: 300,64 | G21: 2,2
A22: 7 | C22: 101314_Batting_fx | D22: 150,380 | E22: 75,380 | F22: 75,380 | G22: 1,1
A23: 8 | C23: 101314_Batting_fx02 | D23: 420,420 | E23: 210,210 | F23: 210,210 | G23: 1,1
A24: 9 | C24: 101314_Batting_Hit_fx | D24: 400,400 | E24: 200,200 | F24: 380,380 | G24: 1,1
A25: 10 | C25: 101434_Batting_jian_fx | D25: 128,400 | E25: 64,400 | F25: 300,64 | G25: 1,1 | H25: -60
A26: 11 | C26: 101434_Batting_jian_fx02 | D26: 200,450 | E26: 100,450 | F26: 300,64 | G26: 1,1 | H26: -60
A27: 12 | C27: 101434_Batting_Hit_fx | D27: 450,450 | E27: 225,225 | F27: 300,64 | G27: 1,1
A28: 13 | C28: 101444_Batting_loop | D28: 150,320 | E28: 75,320 | F28: 75,320 | G28: 1,1
A29: 14 | C29: 101444_Batting_dao | D29: 256,256 | E29: 0,0 | F29: -40,0 | G29: 2,2
A30: 15 | C30: 101444_Batting_Hit | D30: 420,510 | E30: 210,255 | F30: 380,320 | G30: 1,1
A31: 16 | C31: 101484_Batting_fx | D31: 512,256 | E31: 512,128 | F31: 512,128 | G31: 1,1
A32: 17 | C32: 101484_Batting_ball_fx | D32: 100,100 | E32: 50,50 | F32: 512,128 | G32: 1,1
A33: 18 | C33: 101484_Batting_fx_ack | D33: 489,142 | E33: 489,71 | F33: 512,128 | G33: 1,1
A34: 19 | C34: 101484_Batting_Hit_fx | D34: 300,300 | E34: 150,150 | F34: 512,128 | G34: 1,1
