Workbook

Sheet guide_type
A1: ##comment | B1: ID | C1: 大章名id | D1: 任务中文参考 | E1: 排序
A2: ##var | B2: id | C2: type_name | E2: sort
A3: ##type | B3: int32 | C3: int32 | E3: int32
A4: ##group | B4: c,s | C4: c,s | E4: c,s
A5: ## | B5: 引导大类配置 | C5: 0 | E5: 0
B6: 1 | C6: 10000000 | D6: 基础 | E6: 1
B7: 2 | C7: 10000001 | D7: 杀法 | E7: 2
B8: 3 | C8: 10000002 | D8: 战术 | E8: 3
B9: 4 | C9: 10000003 | D9: 布局 | E9: 4

Sheet guide_chapter
A1: ##comment | B1: 章节唯一ID | C1: 所属大章 | D1: 章节图标 | E1: 章节名id | F1: 任务中文参考 | G1: 页签排序 | H1: 章节完成奖励 | I1: 章节名id | J1: 任务中文参考
A2: ##var | B2: id | C2: guide_type | D2: chapter_icon | E2: chapter_name | G2: tap_sort | H2: guide_chapter_reward | I2: reward_txt
A3: ##type | B3: int32 | C3: int32 | D3: string | E3: int32 | G3: int32 | H3: (list#sep=;),reward1 | I3: int32
A4: ##group | B4: c,s | C4: c,s | D4: c | E4: c,s | G4: c,s | H4: c,s | I4: c,s
A5: ## | B5: 引导章节配置 | C5: 0 | D5: 0 | E5: 0 | G5: 0 | H5: [] | I5: 0
B6: =C6*10 -> 10 | C6: 1 | D6: ui_btn_canju_cjcg | E6: =10000000+B6*1000 -> 10010000 | F6: 象棋棋盘 | G6: 1 | H6: 1,1;2,100 | I6: =E6+2 -> 10010002 | J6: ="完成<font color=#028702>"&F6&"</font>所有课程可领取" -> 完成<font color=#028702>象棋棋盘</font>所有课程可领取
B7: =B6+1 -> 11 | C7: 1 | D7: ui_btn_canju_mrcj | E7: =10000000+B7*1000 -> 10011000 | F7: 走子和吃子 | G7: 2 | H7: 1,1;2,101 | I7: =E7+2 -> 10011002 | J7: ="完成<font color=#028702>"&F7&"</font>所有课程可领取" -> 完成<font color=#028702>走子和吃子</font>所有课程可领取
B8: =B7+1 -> 12 | C8: 1 | D8: ui_btn_canju_cjdz | E8: =10000000+B8*1000 -> 10012000 | F8: 如何获胜 | G8: 3 | H8: 1,1;2,102 | I8: =E8+2 -> 10012002 | J8: ="完成<font color=#028702>"&F8&"</font>所有课程可领取" -> 完成<font color=#028702>如何获胜</font>所有课程可领取
B9: =B8+1 -> 13 | C9: 1 | D9: ui_btn_canju_cjxs | E9: =10000000+B9*1000 -> 10013000 | F9: 读谱记录 | G9: 4 | H9: 1,1;2,103 | I9: =E9+2 -> 10013002 | J9: ="完成<font color=#028702>"&F9&"</font>所有课程可领取" -> 完成<font color=#028702>读谱记录</font>所有课程可领取
B10: =C10*10 -> 20 | C10: 2 | D10: ui_btn_canju_sfxl | E10: =10000000+B10*1000 -> 10020000 | F10: 车类杀法 | G10: 1 | H10: 1,1;2,104 | I10: =E10+2 -> 10020002 | J10: ="完成<font color=#028702>"&F10&"</font>所有课程可领取" -> 完成<font color=#028702>车类杀法</font>所有课程可领取
B11: =B10+1 -> 21 | C11: 2 | D11: ui_btn_canju_zsxl | E11: =10000000+B11*1000 -> 10021000 | F11: 马类杀法 | G11: 2 | H11: 1,1;2,105 | I11: =E11+2 -> 10021002 | J11: ="完成<font color=#028702>"&F11&"</font>所有课程可领取" -> 完成<font color=#028702>马类杀法</font>所有课程可领取
B12: =B11+1 -> 22 | C12: 2 | D12: ui_btn_canju_gpdq | E12: =10000000+B12*1000 -> 10022000 | F12: 炮类杀法 | G12: 3 | H12: 1,1;2,106 | I12: =E12+2 -> 10022002 | J12: ="完成<font color=#028702>"&F12&"</font>所有课程可领取" -> 完成<font color=#028702>炮类杀法</font>所有课程可领取
B13: =B12+1 -> 23 | C13: 2 | D13: ui_btn_canju_cjdz | E13: =10000000+B13*1000 -> 10023000 | F13: 兵类杀法 | G13: 4 | H13: 1,1;2,107 | I13: =E13+2 -> 10023002 | J13: ="完成<font color=#028702>"&F13&"</font>所有课程可领取" -> 完成<font color=#028702>兵类杀法</font>所有课程可领取
B14: =B13+1 -> 24 | C14: 2 | D14: ui_btn_canju_cjcg | E14: =10000000+B14*1000 -> 10024000 | F14: 其他杀法 | G14: 5 | H14: 1,1;2,108 | I14: =E14+2 -> 10024002 | J14: ="完成<font color=#028702>"&F14&"</font>所有课程可领取" -> 完成<font color=#028702>其他杀法</font>所有课程可领取
B15: =C15*10 -> 30 | C15: 3 | D15: ui_btn_canju_mrcj | E15: =10000000+B15*1000 -> 10030000 | F15: 运子战术 | G15: 1 | H15: 1,1;2,109 | I15: =E15+2 -> 10030002 | J15: ="完成<font color=#028702>"&F15&"</font>所有课程可领取" -> 完成<font color=#028702>运子战术</font>所有课程可领取
B16: =B15+1 -> 31 | C16: 3 | D16: ui_btn_canju_cjdz | E16: =10000000+B16*1000 -> 10031000 | F16: 谋子战术 | G16: 2 | H16: 1,1;2,110 | I16: =E16+2 -> 10031002 | J16: ="完成<font color=#028702>"&F16&"</font>所有课程可领取" -> 完成<font color=#028702>谋子战术</font>所有课程可领取
B17: =B16+1 -> 32 | C17: 3 | D17: ui_btn_canju_cjxs | E17: =10000000+B17*1000 -> 10032000 | F17: 兑子战术 | G17: 3 | H17: 1,1;2,111 | I17: =E17+2 -> 10032002 | J17: ="完成<font color=#028702>"&F17&"</font>所有课程可领取" -> 完成<font color=#028702>兑子战术</font>所有课程可领取
B18: =B17+1 -> 33 | C18: 3 | D18: ui_btn_canju_sfxl | E18: =10000000+B18*1000 -> 10033000 | F18: 弃子战术 | G18: 4 | H18: 1,1;2,112 | I18: =E18+2 -> 10033002 | J18: ="完成<font color=#028702>"&F18&"</font>所有课程可领取" -> 完成<font color=#028702>弃子战术</font>所有课程可领取
B19: =C19*10 -> 40 | C19: 4 | D19: ui_btn_canju_zsxl | E19: =10000000+B19*1000 -> 10040000 | F19: 开局原理 | G19: 1 | H19: 1,1;2,113 | I19: =E19+2 -> 10040002 | J19: ="完成<font color=#028702>"&F19&"</font>所有课程可领取" -> 完成<font color=#028702>开局原理</font>所有课程可领取
B20: =B19+1 -> 41 | C20: 4 | D20: ui_btn_canju_gpdq | E20: =10000000+B20*1000 -> 10041000 | F20: 炮类开局 | G20: 2 | H20: 1,1;2,114 | I20: =E20+2 -> 10041002 | J20: ="完成<font color=#028702>"&F20&"</font>所有课程可领取" -> 完成<font color=#028702>炮类开局</font>所有课程可领取
B21: =B20+1 -> 42 | C21: 4 | D21: ui_btn_canju_cjdz | E21: =10000000+B21*1000 -> 10042000 | F21: 马类开局 | G21: 3 | H21: 1,1;2,115 | I21: =E21+2 -> 10042002 | J21: ="完成<font color=#028702>"&F21&"</font>所有课程可领取" -> 完成<font color=#028702>马类开局</font>所有课程可领取
B22: =B21+1 -> 43 | C22: 4 | D22: ui_btn_canju_cjcg | E22: =10000000+B22*1000 -> 10043000 | F22: 兵类开局 | G22: 4 | H22: 1,1;2,116 | I22: =E22+2 -> 10043002 | J22: ="完成<font color=#028702>"&F22&"</font>所有课程可领取" -> 完成<font color=#028702>兵类开局</font>所有课程可领取
B23: =B22+1 -> 44 | C23: 4 | D23: ui_btn_canju_mrcj | E23: =10000000+B23*1000 -> 10044000 | F23: 相类开局 | G23: 5 | H23: 1,1;2,117 | I23: =E23+2 -> 10044002 | J23: ="完成<font color=#028702>"&F23&"</font>所有课程可领取" -> 完成<font color=#028702>相类开局</font>所有课程可领取

Sheet guide_lesson
A1: ##comment | B1: 课程ID | C1: 所属章节 | D1: 课程名id | E1: 任务中文参考 | F1: 课程排序
A2: ##var | B2: id | C2: guide_chapter | D2: lesson_name | F2: lesson_sort
A3: ##type | B3: int32 | C3: int32 | D3: int32 | F3: int32
A4: ##group | B4: c,s | C4: c,s | D4: c,s | F4: c,s
A5: ## | B5: 引导课程配置 | C5: 0 | D5: 0 | F5: 0 | K5: 车类杀法 | L5: 马类杀法 | M5: 炮类杀法 | N5: 兵类杀法 | O5: 其他杀法
B6: 100 | C6: 10 | D6: =10000000+B6*1000+1 -> 10100001 | E6: 认识棋盘 | F6: 1 | G6: 1 | H6: =VLOOKUP(C6,guide_chapter!B:F,4,FALSE) -> 10010000 | K6: 双车错 | L6: 卧槽马 | M6: 重炮 | N6: 二鬼拍门 | O6: 白脸将、对面笑
B7: =B6+1 -> 101 | C7: 10 | D7: =10000000+B7*1000+1 -> 10101001 | E7: 棋盘横线术语 | F7: 2 | G7: 2 | H7: =VLOOKUP(C7,guide_chapter!B:F,4,FALSE) -> 10010000 | K7: 双车胁士杀 | L7: 挂角马 | M7: 闷宫 | N7: 送佛归殿 | O7: 三子归边
B8: =B7+1 -> 102 | C8: 10 | D8: =10000000+B8*1000+1 -> 10102001 | E8: 棋盘竖线术语 | F8: 3 | G8: 3 | H8: =VLOOKUP(C8,guide_chapter!B:F,4,FALSE) -> 10010000 | K8: 三车闹士 | L8: 钓鱼马/侧面虎 | M8: 马后炮 | N8: 小鬼坐龙庭 | O8: 臣压君
B9: 110 | C9: 11 | D9: =10000000+B9*1000+1 -> 10110001 | E9: 帅/将 | F9: 1 | G9: 1 | H9: =VLOOKUP(C9,guide_chapter!B:F,4,FALSE) -> 10011000 | K9: 大刀剜心 | L9: 高钓马 | M9: 夹车炮 | N9: 老兵搜山 | O9: 双照将
B10: =B9+1 -> 111 | C10: 11 | D10: =10000000+B10*1000+1 -> 10111001 | E10: 仕/士 | F10: 2 | G10: 2 | H10: =VLOOKUP(C10,guide_chapter!B:F,4,FALSE) -> 10011000 | K10: 海底捞月 | L10: 八角马 | M10: 天地炮 | O10: 闷杀
B11: =B10+1 -> 112 | C11: 11 | D11: =10000000+B11*1000+1 -> 10112001 | E11: 相/象 | F11: 3 | G11: 3 | H11: =VLOOKUP(C11,guide_chapter!B:F,4,FALSE) -> 10011000 | K11: 车马冷着 | L11: 拔簧马 | M11: 空头炮 | O11: 困毙
B12: =B11+1 -> 113 | C12: 11 | D12: =10000000+B12*1000+1 -> 10113001 | E12: 马 | F12: 4 | G12: 4 | H12: =VLOOKUP(C12,guide_chapter!B:F,4,FALSE) -> 10011000 | L12: 白马现蹄/弃车挂玉 | M12: 平顶冠
B13: =B12+1 -> 114 | C13: 11 | D13: =10000000+B13*1000+1 -> 10114001 | E13: 车 | F13: 5 | G13: 5 | H13: =VLOOKUP(C13,guide_chapter!B:F,4,FALSE) -> 10011000 | L13: 双马饮泉 | M13: 铁门栓
B14: =B13+1 -> 115 | C14: 11 | D14: =10000000+B14*1000+1 -> 10115001 | E14: 炮 | F14: 6 | G14: 6 | H14: =VLOOKUP(C14,guide_chapter!B:F,4,FALSE) -> 10011000 | M14: 炮碾丹砂
B15: =B14+1 -> 116 | C15: 11 | D15: =10000000+B15*1000+1 -> 10116001 | E15: 兵 | F15: 7 | G15: 7 | H15: =VLOOKUP(C15,guide_chapter!B:F,4,FALSE) -> 10011000 | M15: 双杯献酒
B16: =B15+1 -> 117 | C16: 11 | D16: =10000000+B16*1000+1 -> 10117001 | E16: 棋子术语 | F16: 8 | G16: 8 | H16: =VLOOKUP(C16,guide_chapter!B:F,4,FALSE) -> 10011000
B17: =B16+1 -> 118 | C17: 11 | D17: =10000000+B17*1000+1 -> 10118001 | E17: 行棋术语 | F17: 9 | G17: 9 | H17: =VLOOKUP(C17,guide_chapter!B:F,4,FALSE) -> 10011000
B18: 120 | C18: 12 | D18: =10000000+B18*1000+1 -> 10120001 | E18: 将死帅/将 | F18: 1 | G18: 1 | H18: =VLOOKUP(C18,guide_chapter!B:F,4,FALSE) -> 10012000
B19: =B18+1 -> 121 | C19: 12 | D19: =10000000+B19*1000+1 -> 10121001 | E19: 将帅碰面 | F19: 2 | G19: 2 | H19: =VLOOKUP(C19,guide_chapter!B:F,4,FALSE) -> 10012000
B20: =B19+1 -> 122 | C20: 12 | D20: =10000000+B20*1000+1 -> 10122001 | E20: 无子可走 | F20: 3 | G20: 3 | H20: =VLOOKUP(C20,guide_chapter!B:F,4,FALSE) -> 10012000
B21: 130 | C21: 13 | D21: =10000000+B21*1000+1 -> 10130001 | E21: 炮/车/卒/帅 | F21: 1 | G21: 1 | H21: =VLOOKUP(C21,guide_chapter!B:F,4,FALSE) -> 10013000
B22: =B21+1 -> 131 | C22: 13 | D22: =10000000+B22*1000+1 -> 10131001 | E22: 马/士/象 | F22: 2 | G22: 2 | H22: =VLOOKUP(C22,guide_chapter!B:F,4,FALSE) -> 10013000
B23: =B22+1 -> 132 | C23: 13 | D23: =10000000+B23*1000+1 -> 10132001 | E23: 名谱练习 | F23: 3 | G23: 3 | H23: =VLOOKUP(C23,guide_chapter!B:F,4,FALSE) -> 10013000
B24: 200 | C24: 20 | D24: =10000000+B24*1000+1 -> 10200001 | E24: 双车错 | F24: 1 | G24: 1 | H24: =VLOOKUP(C24,guide_chapter!B:F,4,FALSE) -> 10020000
B25: =B24+1 -> 201 | C25: 20 | D25: =10000000+B25*1000+1 -> 10201001 | E25: 双车胁士杀 | F25: 2 | G25: 2 | H25: =VLOOKUP(C25,guide_chapter!B:F,4,FALSE) -> 10020000
B26: =B25+1 -> 202 | C26: 20 | D26: =10000000+B26*1000+1 -> 10202001 | E26: 三车闹士 | F26: 3 | G26: 3 | H26: =VLOOKUP(C26,guide_chapter!B:F,4,FALSE) -> 10020000
B27: =B26+1 -> 203 | C27: 20 | D27: =10000000+B27*1000+1 -> 10203001 | E27: 大刀剜心 | F27: 4 | G27: 4 | H27: =VLOOKUP(C27,guide_chapter!B:F,4,FALSE) -> 10020000
B28: =B27+1 -> 204 | C28: 20 | D28: =10000000+B28*1000+1 -> 10204001 | E28: 海底捞月 | F28: 5 | G28: 5 | H28: =VLOOKUP(C28,guide_chapter!B:F,4,FALSE) -> 10020000
B29: =B28+1 -> 205 | C29: 20 | D29: =10000000+B29*1000+1 -> 10205001 | E29: 车马冷着 | F29: 6 | G29: 6 | H29: =VLOOKUP(C29,guide_chapter!B:F,4,FALSE) -> 10020000
B30: 210 | C30: 21 | D30: =10000000+B30*1000+1 -> 10210001 | E30: 卧槽马 | F30: 6 | G30: 6 | H30: =VLOOKUP(C30,guide_chapter!B:F,4,FALSE) -> 10021000
B31: =B30+1 -> 211 | C31: 21 | D31: =10000000+B31*1000+1 -> 10211001 | E31: 挂角马 | F31: 1 | G31: 1 | H31: =VLOOKUP(C31,guide_chapter!B:F,4,FALSE) -> 10021000
B32: =B31+1 -> 212 | C32: 21 | D32: =10000000+B32*1000+1 -> 10212001 | E32: 钓鱼马/侧面虎 | F32: 2 | G32: 2 | H32: =VLOOKUP(C32,guide_chapter!B:F,4,FALSE) -> 10021000
B33: =B32+1 -> 213 | C33: 21 | D33: =10000000+B33*1000+1 -> 10213001 | E33: 高钓马 | F33: 3 | G33: 3 | H33: =VLOOKUP(C33,guide_chapter!B:F,4,FALSE) -> 10021000
B34: =B33+1 -> 214 | C34: 21 | D34: =10000000+B34*1000+1 -> 10214001 | E34: 八角马 | F34: 4 | G34: 4 | H34: =VLOOKUP(C34,guide_chapter!B:F,4,FALSE) -> 10021000
B35: =B34+1 -> 215 | C35: 21 | D35: =10000000+B35*1000+1 -> 10215001 | E35: 拔簧马 | F35: 5 | G35: 5 | H35: =VLOOKUP(C35,guide_chapter!B:F,4,FALSE) -> 10021000
B36: =B35+1 -> 216 | C36: 21 | D36: =10000000+B36*1000+1 -> 10216001 | E36: 白马现蹄/弃车挂玉 | F36: 6 | G36: 6 | H36: =VLOOKUP(C36,guide_chapter!B:F,4,FALSE) -> 10021000
B37: =B36+1 -> 217 | C37: 21 | D37: =10000000+B37*1000+1 -> 10217001 | E37: 双马饮泉 | F37: 7 | G37: 7 | H37: =VLOOKUP(C37,guide_chapter!B:F,4,FALSE) -> 10021000
B38: 220 | C38: 22 | D38: =10000000+B38*1000+1 -> 10220001 | E38: 重炮 | F38: 1 | G38: 1 | H38: =VLOOKUP(C38,guide_chapter!B:F,4,FALSE) -> 10022000
B39: =B38+1 -> 221 | C39: 22 | D39: =10000000+B39*1000+1 -> 10221001 | E39: 闷宫 | F39: 2 | G39: 2 | H39: =VLOOKUP(C39,guide_chapter!B:F,4,FALSE) -> 10022000
B40: =B39+1 -> 222 | C40: 22 | D40: =10000000+B40*1000+1 -> 10222001 | E40: 马后炮 | F40: 3 | G40: 3 | H40: =VLOOKUP(C40,guide_chapter!B:F,4,FALSE) -> 10022000
...

Sheet guide_display
A1: ##comment | B1: 引导id | C1: 所属课程id | D1: 显示分类 | E1: 标题和页签语言包 | F1: 引导说明文本 | G1: 显示排序 | H1: 课程总结图
A2: ##var | B2: id | C2: guide_chapter | D2: display_type | E2: title_id | G2: sort | H2: chapter_all_bg
A3: ##type | B3: int32 | C3: int32 | D3: int32 | E3: int32 | G3: int32 | H3: string
A4: ##group | B4: c,s | C4: c,s | D4: c,s | E4: c,s | G4: c,s | H4: c,s
A5: ## | B5: 引导显示配置 | C5: 0 | D5: 0 | E5: 0 | G5: 0 | H5: 0
B6: 1 | C6: 100 | D6: 1 | E6: =VLOOKUP(C6,guide_lesson!B:D,3,FALSE)+99 -> 10100100 | F6: 认识棋盘 | G6: 1 | H6: qipan1
B7: 2 | C7: 101 | D7: 1 | E7: =VLOOKUP(C7,guide_lesson!B:D,3,FALSE)+99 -> 10101100 | F7: 棋盘横线术语 | G7: 1 | H7: qipan2
B8: 3 | C8: 102 | D8: 1 | E8: =VLOOKUP(C8,guide_lesson!B:D,3,FALSE)+99 -> 10102100 | F8: 棋盘竖线术语 | G8: 1 | H8: qipan3
B9: 10 | C9: 110 | D9: 1 | E9: =VLOOKUP(C9,guide_lesson!B:D,3,FALSE)+99 -> 10110100 | F9: 帅/将走法 | G9: 1
B10: 11 | C10: 110 | D10: 1 | E10: =E9+100 -> 10110200 | F10: 帅/将吃法 | G10: 2 | H10: qipan4
B11: 12 | C11: 110 | D11: 2 | E11: =E10+100 -> 10110300 | F11: 习题1 | G11: 1
B12: 13 | C12: 110 | D12: 2 | E12: =E11+100 -> 10110400 | F12: 习题2 | G12: 2
B13: 14 | C13: 110 | D13: 2 | E13: =E12+100 -> 10110500 | F13: 习题3 | G13: 3
B14: 15 | C14: 110 | D14: 2 | E14: =E13+100 -> 10110600 | F14: 习题4 | G14: 4 | H14: qipan0
B15: 20 | C15: 111 | D15: 1 | E15: =VLOOKUP(C15,guide_lesson!B:D,3,FALSE)+99 -> 10111100 | F15: 仕/士走法 | G15: 1
B16: 21 | C16: 111 | D16: 1 | E16: =E15+100 -> 10111200 | F16: 仕/士吃法 | G16: 2
B17: 22 | C17: 111 | D17: 2 | E17: =E16+100 -> 10111300 | F17: 习题1 | G17: 1
B18: 23 | C18: 111 | D18: 2 | E18: =E17+100 -> 10111400 | F18: 习题2 | G18: 2
B19: 24 | C19: 111 | D19: 2 | E19: =E18+100 -> 10111500 | F19: 习题3 | G19: 3
B20: 25 | C20: 111 | D20: 2 | E20: =E19+100 -> 10111600 | F20: 习题4 | G20: 4
B21: 26 | C21: 111 | D21: 2 | E21: =E20+100 -> 10111700 | F21: 测试习题 | G21: 4
B22: 30 | C22: 112 | D22: 1 | E22: =VLOOKUP(C22,guide_lesson!B:D,3,FALSE)+99 -> 10112100 | F22: 相/象走法 | G22: 1
B23: 31 | C23: 112 | D23: 1 | E23: =E22+100 -> 10112200 | F23: 相/象吃法 | G23: 2
B24: 32 | C24: 112 | D24: 2 | E24: =E23+100 -> 10112300 | F24: 习题1 | G24: 1
B25: 33 | C25: 112 | D25: 2 | E25: =E24+100 -> 10112400 | F25: 习题2 | G25: 2
B26: 34 | C26: 112 | D26: 2 | E26: =E25+100 -> 10112500 | F26: 习题3 | G26: 3
B27: 35 | C27: 112 | D27: 2 | E27: =E26+100 -> 10112600 | F27: 习题4 | G27: 4
B28: 36 | C28: 112 | D28: 2 | E28: =E27+100 -> 10112700 | F28: 习题5 | G28: 5
B29: 40 | C29: 113 | D29: 1 | E29: =VLOOKUP(C29,guide_lesson!B:D,3,FALSE)+99 -> 10113100 | F29: 马走法 | G29: 1
B30: 41 | C30: 113 | D30: 1 | E30: =E29+100 -> 10113200 | F30: 马吃法 | G30: 2
B31: 42 | C31: 113 | D31: 2 | E31: =E30+100 -> 10113300 | F31: 习题1 | G31: 1
B32: 43 | C32: 113 | D32: 2 | E32: =E31+100 -> 10113400 | F32: 习题2 | G32: 2
B33: 44 | C33: 113 | D33: 2 | E33: =E32+100 -> 10113500 | F33: 习题3 | G33: 3
B34: 45 | C34: 113 | D34: 2 | E34: =E33+100 -> 10113600 | F34: 习题4 | G34: 4
B35: 46 | C35: 113 | D35: 2 | E35: =E34+100 -> 10113700 | F35: 习题5 | G35: 5
B36: 50 | C36: 114 | D36: 1 | E36: =VLOOKUP(C36,guide_lesson!B:D,3,FALSE)+99 -> 10114100 | F36: 车走法 | G36: 1
B37: 51 | C37: 114 | D37: 1 | E37: =E36+100 -> 10114200 | F37: 车吃法 | G37: 2
B38: 52 | C38: 114 | D38: 2 | E38: =E37+100 -> 10114300 | F38: 习题1 | G38: 1
B39: 53 | C39: 114 | D39: 2 | E39: =E38+100 -> 10114400 | F39: 习题2 | G39: 2
B40: 54 | C40: 114 | D40: 2 | E40: =E39+100 -> 10114500 | F40: 习题3 | G40: 3
...

Sheet guide_step
A1: ##comment | B1: 引导id | C1: 步骤 | D1: 步骤类型 | E1: 步骤参数 | F1: 箭头类型位置 | G1: 箭头数字 | H1: 标记点位置 | I1: 特殊文字位置 | J1: 指引线位置 | K1: 指引框位置 | L1: 手指位置 | M1: 手指滑动位置 | N1: 文本框位置 | O1: 文本框语言包 | P1: 引导说明文本 | Q1: 特殊文字语言包 | S1: 操作错误提示 | T1: 操作错误文本 | U1: 该步骤生成星星 | V1: 该步骤生成棋谱 | W1: 自动播放时间 | X1: 自动播放切换方式
A2: ##var | B2: id | C2: step | D2: guide_type | E2: guide_type_param | F2: arrow_xy | G2: arrow_num | H2: point_xy | I2: special_xy | J2: position_line_xy | K2: position_box_xy | L2: finger_xy | M2: finger_xy2 | N2: txt_box_xy | O2: txt_language | Q2: special_txt | S2: bug_txt | U2: xingx | V2: qipu | W2: autoplay_time | X2: autoplay_type
A3: ##type | B3: int32 | C3: int32 | D3: int32 | E3: string | F3: (list#sep=;),xy5 | G3: (list#sep=,),int | H3: (list#sep=;),xy3 | I3: (list#sep=;),xy1 | J3: (list#sep=;),xy2 | K3: (list#sep=;),xy2 | L3: (list#sep=;),xy3 | M3: (list#sep=;),xy4 | N3: xy4 | O3: int32 | Q3: (list#sep=;),int | S3: int32 | U3: (list#sep=;),xy1 | V3: string | W3: int32 | X3: int32
A4: ##group | B4: c,s | C4: c,s | D4: c,s | E4: c,s | F4: c,s | G4: c,s | H4: c,s | I4: c,s | J4: c,s | K4: c,s | L4: c,s | M4: c,s | N4: c,s | O4: c,s | Q4: c,s | S4: c,s | U4: c,s | V4: c,s | W4: c,s | X4: c,s
A5: ## | B5: 引导配置 | C5: 0 | D5: 0 | E5: 0 | O5: 0 | Q5: 0 | S5: 0 | W5: 0 | X5: 0
B6: 1 | C6: 1 | D6: 1 | K6: -0.5,4,8.5,-0.5 | L6: 3,7,4 | N6: 1,6.5,7,0,0 | O6: =VLOOKUP(B6,guide_display!B:E,4,FALSE)+1 -> 10100101 | P6: 象棋分为两个阵营，<font color=#f80421>红色棋子</font>一方为<font color=#f80421>红色阵营</font>，在游戏中为<font color=#048404>先手方</font> | V6: rnbakabnr/9/1c5c1/p1p1p1p1p/9/9/P1P1P1P1P/1C5C1/9/RNBAKABNR | W6: 2
B7: 1 | C7: 2 | D7: 1 | K7: -0.5,9.5,8.5,5 | L7: 1,7,5 | N7: 1,6.5,3,0,0 | O7: =O6+1 -> 10100102 | P7: <font color=#000000>黑色棋子</font>一方为<font color=#f80421>黑方阵营</font>，在游戏中属于<font color=#048404>后手方</font> | V7: rnbakabnr/9/1c5c1/p1p1p1p1p/9/9/P1P1P1P1P/1C5C1/9/RNBAKABNR | W7: 2
B8: 1 | C8: 3 | D8: 1 | K8: 0,5,8,4 | L8: 1,7,4 | N8: 1,6.5,3,0,0 | O8: =O7+1 -> 10100103 | P8: 棋盘中间的<font color=#048404>楚河汉界</font>，一般被称呼<font color=#048404>河界</font> | V8: rnbakabnr/9/1c5c1/p1p1p1p1p/9/9/P1P1P1P1P/1C5C1/9/RNBAKABNR | W8: 2
B9: 1 | C9: 4 | D9: 1 | K9: 3,2,5,0;3,9,5,7 | L9: 3,5,1;1,5,8 | N9: 1,6.5,5.3,0,0 | O9: =O8+1 -> 10100104 | P9: <font color=#f80421>帅</font>/<font color=#000000>将</font>、<font color=#f80421>仕</font>/<font color=#000000>士</font>所在的<font color=#048404>米字方格</font>，一般被称呼<font color=#048404>九宫</font>，代表九个线条交叉点。 | V9: rnbakabnr/9/1c5c1/p1p1p1p1p/9/9/P1P1P1P1P/1C5C1/9/RNBAKABNR | W9: 2
B10: 1 | C10: 5 | D10: 1 | K10: -0.5,-0.5,8.5,-1;-0.5,10,8.5,9.5 | L10: 3,6,-0.4;1,6,9.4 | N10: 1,6.5,5.3,0,0 | O10: =O9+1 -> 10100105 | P10: 下方为己方，标注<font color=#048404>一至九</font>，上方棋盘为敌方，标注<font color=#048404>9至1</font>，这些数字称为<font color=#048404>位标</font> | V10: rnbakabnr/9/1c5c1/p1p1p1p1p/9/9/P1P1P1P1P/1C5C1/9/RNBAKABNR | W10: 2
B11: 2 | C11: 1 | D11: 1 | I11: 4,9 | J11: 4,9,4,0 | L11: 1,4,4 | N11: 1,6.5,0,0,0 | O11: =VLOOKUP(B11,guide_display!B:E,4,FALSE)+1 -> 10101101 | P11: 棋盘中第五条竖线称为<font color=#048404>中线</font> | Q11: 1101104 | R11: 中线 | W11: 2
B12: =B11 -> 2 | C12: =C11+1 -> 2 | D12: 1 | I12: 3,9;5,9 | J12: 3,9,3,0;5,9,5,0 | L12: 2,3,4;1,5,4 | N12: 1,6.5,0,0,0 | O12: =O11+1 -> 10101102 | P12: 棋盘中第四和第六条竖线，称为<font color=#048404>肋道</font> | Q12: 1101105;1101105 | R12: 肋道,肋道 | W12: 2
B13: =B12 -> 2 | C13: =C12+1 -> 3 | D13: 1 | I13: 0,9;8,9 | J13: 0,9,0,0;8,9,8,0 | L13: 1,0,4;2,8,4 | N13: 1,6.5,0,0,0 | O13: =O12+1 -> 10101103 | P13: 棋盘中第一和第九条竖线，称为<font color=#048404>边线</font> | Q13: 1101106;1101106 | R13: 边线,边线 | W13: 2
B14: 3 | C14: 1 | D14: 1 | I14: 8,0;8,9 | J14: 0,0,8,0;0,9,8,9 | L14: 3,6,0;1,6,9 | N14: 1,6.5,5,0,0 | O14: =VLOOKUP(B14,guide_display!B:E,4,FALSE)+1 -> 10102101 | P14: 以棋手为准，双方由下至上第一条横线称为<font color=#048404>底线</font> | Q14: 1102106;1102106 | R14: 底线,底线, | W14: 2
B15: 3 | C15: =C14+1 -> 2 | D15: 1 | I15: ,8,1;8,8 | J15: 0,1,8,1;0,8,8,8 | L15: 3,6,1;1,6,8 | N15: 1,6.5,5,0,0 | O15: =O14+1 -> 10102102 | P15: 以棋手为准，双方由下至上第二条横线称为<font color=#048404>底二线</font> | Q15: 1102107;1102107 | R15: 底二线;底二线 | W15: 2
B16: 3 | C16: =C15+1 -> 3 | D16: 1 | I16: 8,2;8,7 | J16: 0,2,8,2;0,7,8,7 | L16: 3,6,2;1,6,7 | N16: 1,6.5,5,0,0 | O16: =O15+1 -> 10102103 | P16: 以棋手为准，双方由下至上第三条横线称为<font color=#048404>宫顶线</font> | Q16: 1102108;1102108 | R16: 宫顶线,宫顶线 | W16: 2
B17: 3 | C17: =C16+1 -> 4 | D17: 1 | I17: 8,3;8,6 | J17: 0,3,8,3;0,6,8,6 | L17: 3,6,3;1,6,6 | N17: 1,6.5,2,0,0 | O17: =O16+1 -> 10102104 | P17: 以棋手为准，双方由下至上第四条横线称为<font color=#048404>兵行线/卒林线</font>，这是兵和卒的初始位置 | Q17: 1102109;1102111 | R17: 兵行线,卒林线 | W17: 2
B18: 3 | C18: =C17+1 -> 5 | D18: 1 | I18: 8,4;8,5 | J18: 0,4,8,4;0,5,8,5 | L18: 1,6,4;3,6,5 | N18: 1,6.5,2,0,0 | O18: =O17+1 -> 10102105 | P18: 河界两边的线称为<font color=#048404>河界线</font>，这是兵和卒的初始位置 | Q18: 1102110;1102110 | R18: 河界线,河界线 | W18: 2
B19: 10 | C19: 1 | D19: 1 | K19: 3,2,5,0;3,9,5,7 | L19: 3,5,1;1,5,8 | N19: 1,6.5,5,0,0 | O19: =VLOOKUP(B19,guide_display!B:E,4,FALSE)+1 -> 10110101 | P19: <font color=#f80421>帅</font>/<font color=#000000>将</font>只能在<font color=#048404>九宫格</font>内移动，不能走出<font color=#048404>九宫格</font> | V19: 4k4/9/9/9/9/9/9/9/9/4K4 | W19: 2
B20: 10 | C20: 2 | D20: 1 | H20: 2,3,9;2,4,9;2,5,9;2,3,8;2,4,8;2,5,8;2,3,7;2,4,7;2,5,7;1,3,2;1,4,2;1,5,2;1,3,1;1,4,1;1,5,1;1,3,0;1,4,0;1,5,0; | J20: 3,9,3,7;3,9,5,9;5,9,5,7;5,7,3,7;3,8,5,8;4,9,4,7;3,2,3,0;3,2,5,2;5,2,5,0;5,0,3,0;3,1,5,1;4,2,4,0 | L20: 3,5,1;1,5,7.8 | N20: 1,6.5,5,0,0 | O20: =O19+1 -> 10110102 | P20: <font color=#f80421>帅</font>/<font color=#000000>将</font>沿九宫格<font color=#048404>横线和竖线</font>移动，且每次只能移动<font color=#048404>一格</font> | W20: 2
B21: 10 | C21: 3 | D21: 1 | F21: 1,4,0,4,1;1,4,0,3,0;1,4,0,5,0; | H21: 1,3,0;1,5,0;1,4,1 | L21: 3,5,1 | N21: 1,6.5,3.5,0,0 | O21: =O20+1 -> 10110103 | P21: 例如：这里的<font color=#f80421>帅</font>所在位置，就只可向<font color=#048404>上、左、右</font>移动一格 | V21: 9/4k4/9/9/9/9/9/9/9/4K4 | W21: 2
B22: 10 | C22: 4 | D22: 1 | F22: 1,4,0,4,1;1,4,0,3,0;1,4,0,5,0;1,4,8,3,8;1,4,8,5,8;1,4,8,4,9;1,4,8,4,7 | H22: 1,3,0;1,5,0;1,4,1;2,3,8;2,4,7;2,5,8;2,4,9 | L22: 1,5,8 | N22: 1,6.5,6,0,0 | O22: =O21+1 -> 10110104 | P22: 而这里的<font color=#000000>将</font>所在位置，就可向<font color=#048404>上、下、左、右</font>移动一格 | V22: 9/4k4/9/9/9/9/9/9/9/4K4 | W22: 2
B23: 10 | C23: 5 | D23: 1 | F23: 1,4,0,4,1;1,4,0,5,0;2,3,9,3,0 | H23: 1,5,0;1,4,1 | L23: 1,3,9;3,5,1 | N23: 1,7.5,-0.5,100,0 | O23: =O22+1 -> 10110105 | P23: 注意！对局时<font color=#f80421>帅</font>/<font color=#000000>将</font>中间无棋子时，不可在同一竖线上，所以，这个<font color=#f80421>帅</font>此时只能向<font color=#048404>下、右</font>移动一格 | V23: 3k5/9/9/9/9/9/9/9/9/4K4 | W23: 2
B24: 11 | C24: 1 | D24: 1 | J24: 3,9,3,7;3,9,5,9;5,9,5,7;5,7,3,7;3,8,5,8;4,9,4,7;3,2,3,0;3,2,5,2;5,2,5,0;5,0,3,0;3,1,5,1;4,2,4,0 | L24: 3,5,1;1,5,8 | N24: 1,6.5,5,0,0 | O24: =VLOOKUP(B24,guide_display!B:E,4,FALSE)+1 -> 10110201 | P24: <font color=#f80421>帅</font>/<font color=#000000>将</font>的走棋和吃棋方式相同，即沿<font color=#048404>九宫的横线和竖线移动一格</font>吃子 | V24: 9/4k4/9/9/9/9/9/9/9/4K4 | W24: 2
B25: 11 | C25: =C24+1 -> 2 | D25: 1 | F25: 1,4,0,4,1;1,4,0,3,0;1,4,0,5,0;1,4,8,3,8;1,4,8,5,8;1,4,8,4,9;1,4,8,4,7 | L25: 3,5,1;1,5,8 | N25: 1,6.5,5,0,0 | O25: =O24+1 -> 10110202 | P25: 这里的星星，就是当前<font color=#f80421>帅</font>/<font color=#000000>将</font>可以<font color=#048404>吃棋</font>的位置 | U25: 3,0;5,0;4,1;3,8;4,7;5,8;4,9 | V25: 9/4k4/9/9/9/9/9/9/9/4K4 | W25: 2
B26: 11 | C26: =C25+1 -> 3 | D26: 1 | F26: 1,5,0,4,0 | L26: 4,3.8,1 | N26: 1,6.5,5,0,0 | O26: =O25+1 -> 10110203 | P26: 我们再来看这几个星星，由于<font color=#f80421>帅</font>不能斜线移动，所以<font color=#f80421>帅</font>是<font color=#048404不可以吃掉></font>这颗星星的 | U26: 4,1;4,0;5,2;6,0 | V26: 9/9/9/9/9/9/9/9/9/5K3 | W26: 2
B27: 11 | C27: =C26+1 -> 4 | D27: 1 | F27: 1,5,0,4,0 | L27: 1,6.2,0 | N27: 1,6.5,5,0,0 | O27: =O26+1 -> 10110204 | P27: 由于<font color=#f80421>帅</font>不能走出九宫格，所以<font color=#f80421>帅</font>也是<font color=#048404>不可以吃掉</font>这颗星星的 | U27: 4,1;4,0;5,2;6,0 | V27: 9/9/9/9/9/9/9/9/9/5K3 | W27: 2
B28: 11 | C28: =C27+1 -> 5 | D28: 1 | F28: 1,5,0,4,0 | L28: 1,5.2,2 | N28: 1,6.5,5,0,0 | O28: =O27+1 -> 10110205 | P28: 这颗星星的虽然在九宫格，但是<font color=#f80421>帅</font>每次只能移动一格，所以<font color=#f80421>帅</font>也是<font color=#048404>不可以在下一步</font>吃掉这颗星星的 | U28: 4,1;4,0;5,2;6,0 | V28: 9/9/9/9/9/9/9/9/9/5K3 | W28: 2
B29: 11 | C29: =C28+1 -> 6 | D29: 1 | F29: 1,5,0,4,0 | L29: 2,3.8,0 | N29: 1,6.5,5,0,0 | O29: =O28+1 -> 10110206 | P29: 只有这颗星星，在<font color=#f80421>帅</font>旁边横线一格距离，所以<font color=#f80421>帅</font>可以移动过去<font color=#048404>吃掉</font>这颗星星 | U29: 4,1;4,0;5,2;6,0 | V29: 9/9/9/9/9/9/9/9/9/5K3 | W29: 2
B30: 11 | C30: =C29+1 -> 7 | D30: 1 | N30: 1,6.5,5,0,0 | O30: =O29+1 -> 10110207 | P30: 接下来，就让我们去习题实操练习下怎么走<font color=#f80421>帅</font>和吃棋吧！ | W30: 2
B31: 12 | C31: 1 | D31: 3 | E31: K,4,0,5,0,0 | L31: 2,4,0 | N31: 1,6.5,4,0,0 | O31: =VLOOKUP(B31,guide_display!B:E,4,FALSE)+1 -> 10110301 | P31: 点击<font color=#f80421>帅</font>即可选中他，然后再点击<font color=#048404>星星</font>，即可移动到星星位置。试试吧，把<font color=#f80421>帅</font>移动到<font color=#048404>星星</font>位置！ | U31: 5,0 | V31: 9/9/9/9/9/9/9/9/9/4K4
B32: 12 | C32: =C31+1 -> 2 | D32: 3 | E32: K,5,0,5,1,0 | L32: 2,5,0 | N32: 1,6.5,4,0,0 | O32: =O31+1 -> 10110302 | P32: 做得很好！继续把<font color=#f80421>帅</font>移动到新的<font color=#048404>星星</font>位置吧！ | U32: 5,1 | V32: 9/9/9/9/9/9/9/9/9/5K3
B33: 12 | C33: =C32+1 -> 3 | D33: 3 | E33: K,5,1,4,1,0 | N33: 1,6.5,4,0,0 | O33: =O32+1 -> 10110303 | P33: 做得非常好！再试试把<font color=#f80421>帅</font>移动到新的<font color=#048404>星星</font>位置吧！ | U33: 4,1 | V33: 9/9/9/9/9/9/9/9/5K3/9
B34: 12 | C34: =C33+1 -> 4 | D34: 3 | E34: K,4,1,4,2,0 | N34: 1,6.5,4,0,0 | O34: =O33+1 -> 10110304 | P34: 做得真是太棒了！再试试把<font color=#f80421>帅</font>移动到新的<font color=#048404>星星</font>位置吧！ | U34: 4,2 | V34: 9/9/9/9/9/9/9/9/4K4/9
B35: 12 | C35: =C34+1 -> 5 | D35: 1 | N35: 1,6.5,4,0,0 | O35: =O34+1 -> 10110305 | P35: 您真是非常非常优秀！接下来，我们提升下难度吧！ | V35: 9/9/9/9/9/9/9/4K4/9/9 | W35: 2
B36: 13 | C36: 1 | D36: 3 | E36: K,4,0,4,2,0 | N36: 1,6.5,4,0,0 | O36: =VLOOKUP(B36,guide_display!B:E,4,FALSE)+1 -> 10110401 | P36: 这次需要移动<font color=#f80421>帅</font>两步，才能移动到<font color=#048404>星星</font>位置哟！试试吧！ | U36: 4,2 | V36: 9/9/9/9/9/9/9/9/9/4K4
B37: 13 | C37: =C36+1 -> 2 | D37: 3 | E37: K,4,2,5,0,0 | N37: 1,6.5,4,0,0 | O37: =O36+1 -> 10110402 | P37: 很好！这次需要移动<font color=#f80421>帅</font>三步，才能移动到<font color=#048404>星星</font>位置哟！试试吧！ | U37: 5,0 | V37: 9/9/9/9/9/9/9/4K4/9/9
B38: 13 | C38: =C37+1 -> 3 | D38: 3 | E38: K,5,0,3,2,0 | N38: 1,6.5,4,0,0 | O38: =O37+1 -> 10110403 | P38: 真是太棒了！这需要移动<font color=#f80421>帅</font>四步，才能移动到<font color=#048404>星星</font>位置哟！再试试吧！ | U38: 3,2 | V38: 9/9/9/9/9/9/9/9/9/5K3
B39: 13 | C39: =C38+1 -> 4 | D39: 1 | N39: 1,6.5,4,0,0 | O39: =O38+1 -> 10110404 | P39: 您简直太优秀了！接下来，我们试下吃子吧！ | V39: 9/9/9/9/9/9/9/3K5/9/9 | W39: 2
B40: 14 | C40: 1 | D40: 3 | E40: K,4,0,3,0,0 | N40: 1,6.5,4,0,0 | O40: =VLOOKUP(B40,guide_display!B:E,4,FALSE)+1 -> 10110501 | P40: 拿起<font color=#f80421>帅</font>，吃掉旁边的<font color=#048404>黑马</font>吧！ | V40: 9/9/9/9/9/9/9/9/9/3nK4
...

Sheet 棋子棋盘对应
R6: 步骤类型
R7: 1、纯展示文本和引导框，填1
R8: 2、点击按钮,填：2,按钮名，是否手指引导，是否框引导
R9: 3、指定棋子吃星星位置点的星星，填：3, 指定棋子, 棋子棋盘xy位置
R10: 4、指定棋子吃指定位置的棋子，填：4,指定棋子, 棋子棋盘xy位置,被吃棋子,被吃棋子棋盘xy位置
R11: 5、玩家手动移动指定棋子到指定位置,填：5, 指定棋子, 棋子棋盘xy位置，移动目标棋盘xy位置点,移动方式
B12: 棋盘xy位置 | I12: 云指令库中的象棋位置 | R12: 6、按棋谱走子,填：6,云库指令格式的棋谱
R13: 7、用指定杀法将军，填：7,杀法类型
R15: 棋盘的xy点以棋盘的最左下方的x轴和y轴初始位置为0,0点，从左到右为0至8，y轴从下到上是0至10；y轴如果向下，则为-1；值需支持小数点，比如填“0,0.5”，则表示位置点在x轴0，y轴0到1之间一半的地方
R21: rnbakabnr/9/1c5c1/p1p1p1p1p/9/9/P1P1P1P1P/1C5C1/9/RNBAKABNR w moves h2e2 h7e7
R23: 英文 | S23: 棋子 | U23: 英文 | V23: 棋子
R24: r | S24: 黑车 | U24: R | V24: 红车
R25: n | S25: 黑马 | U25: N | V25: 红马
R26: b | S26: 黑象 | U26: B | V26: 红相
R27: a | S27: 黑士 | U27: A | V27: 红仕
R28: k | S28: 黑将 | U28: K | V28: 红帅
R29: c | S29: 黑炮 | U29: C | V29: 红炮
R30: p | S30: 黑卒 | U30: P | V30: 红兵
R32: w | S32: 白方走棋
R33: b | S33: 黑方走棋
R34: moves | S34: 移动
R35: h2e2 | S35: 从h2移动到e2
R36: h7e7 | S36: 从h7移动到e7
D44: 2,1;3,1;4,1
D45: 5,1

Sheet 杀法类型
D1: 类型
D2: 1 | E2: 双车错
E3: 3k5/7R1/6R2/9/p8/9/9/9/9/4K4
D5: 2 | E5: 侧面虎
E6: 3k1a3/4a4/9/2R6/N8/9/6n2/5K3/4r4/9
D8: 3 | E8: 马后炮
E9: 2bakab2/9/9/5N2C/9/9/4c2n1/4B4/4A4/2BAK4
D11: 4 | E11: 重炮
E12: 2bakab2/9/c8/4C4/9/7C1/9/4B4/4A4/2c1KAB2
D14: 5 | E14: 对面笑
E15: 5k5/9/9/9/9/3R5/9/9/9/4K4
D17: 6 | E17: 列马车
E18: 4ka2R/9/6N2/9/9/9/9/9/9/5K3
D20: 7 | E20: 钓鱼马
E21: 4k4/2R6/2N6/9/9/9/9/9/9/5K3
D23: 8 | E23: 八角马
E24: 4ka3/8R/9/7N1/9/9/9/9/4A4/crBAK4
D26: 9 | E26: 双将
E27: 3aka3/9/9/9/4N4/4R4/4C4/9/9/4K4
D29: 10 | E29: 闷宫
E30: 2b1ka3/4a4/4b1C2/9/6c2/6C2/9/9/4K4/9
D32: 11 | E32: 闷杀(待更新fen)
E33: 1N2knb2/4n4/4b4/9/C8/9/4C4/9/9/4K4
D35: 12 | E35: 铁门栓（车）
E36: 3ak1b2/4a4/4b4/4CR3/7r1/9/1pp6/4B4/4A4/3A1KB2
D38: 13 | E38: 铁门栓（兵）
E39: 3ak1b2/4aP3/4b4/4C4/7r1/9/1pp6/4B4/4A4/3A1KB2
D41: 14 | E41: 二鬼拍门
E42: 4kab2/3P1P3/4b4/9/9/9/9/9/3p2p2/4K4
D44: 15 | E44: 天地炮
E45: 1Cbak4/3Pa4/4b4/4C4/7r1/9/1pp6/4B4/4A4/3A1KB2
D47: 16 | E47: 困毙
E48: 3k5/9/4P4/9/9/9/9/4B4/4A4/3A1KB2
